Workbook

Sheet Digital Marketing Budget
B1: ONLINE MARKETING BUDGET
N2: JAHRESAUSGABEN: | O2: =O19 -> 15459
B4: 2022 | C4: Q1 | F4: Q2 | I4: Q3 | L4: Q4 | O4: FISCAL YEAR TOTALS
C5: JAN | D5: FEB | E5: MAR | F5: APR | G5: MAY | H5: JUN | I5: JUL | J5: AUG | K5: SEPT | L5: OCT | M5: NOV | N5: DEC
B6: Marketing Maßnahmen | C6: =SUM(C7:C14) -> 0 | D6: =SUM(D7:D14) -> 0 | E6: =SUM(E7:E14) -> 0 | F6: =SUM(F7:F14) -> 51 | G6: =SUM(G7:G14) -> 51 | H6: =SUM(H7:H14) -> 51 | I6: =SUM(I7:I14) -> 51 | J6: =SUM(J7:J14) -> 51 | ... N6: =SUM(N7:N14) -> 5051 | O6: =SUM(C6:N6) -> 15459
B7: SEO - Offpage | C7: 0 | D7: 0 | E7: 0 | F7: =(1*Kanäle!$B$7)+(1*Kanäle!$C$7)+(1*Kanäle!$D$7)+(1*Kanäle!$E$7) -> 0 | G7: =(1*Kanäle!$B$7)+(1*Kanäle!$C$7)+(1*Kanäle!$D$7)+(1*Kanäle!$E$7) -> 0 | H7: =(1*Kanäle!$B$7)+(1*Kanäle!$C$7)+(1*Kanäle!$D$7)+(1*Kanäle!$E$7) -> 0 | I7: =(1*Kanäle!$B$7)+(2*Kanäle!$C$7)+(2*Kanäle!$D$7)+(2*Kanäle!$E$7) -> 0 | J7: =(1*Kanäle!$B$7)+(2*Kanäle!$C$7)+(2*Kanäle!$D$7)+(2*Kanäle!$E$7) -> 0 | K7: =(1*Kanäle!$B$7)+(2*Kanäle!$C$7)+(2*Kanäle!$D$7)+(2*Kanäle!$E$7) -> 0 | L7: 5000 | M7: 5000 | N7: 5000 | O7: =SUM(C7:N7) -> 15000
B8: Content+SEO | C8: 0 | D8: 0 | E8: 0 | F8: =Kanäle!$D$11+Kanäle!$E$11 -> 0 | G8: =Kanäle!$D$11+Kanäle!$E$11 -> 0 | H8: =Kanäle!$D$11+Kanäle!$E$11 -> 0 | I8: =Kanäle!$D$11+Kanäle!$E$11 -> 0 | J8: =Kanäle!$D$11+Kanäle!$E$11 -> 0 | K8: =Kanäle!$D$11+Kanäle!$E$11 -> 0 | L8: =Kanäle!$D$11+Kanäle!$E$11 -> 0 | M8: =Kanäle!$D$11+Kanäle!$E$11 -> 0 | N8: =Kanäle!$D$11+Kanäle!$E$11 -> 0 | O8: =SUM(C8:N8) -> 0
B9: Content Marketing | C9: 0 | D9: 0 | E9: 0 | F9: 0 | G9: 0 | H9: =Kanäle!$B$15+Kanäle!$C$15+Kanäle!$D$15+Kanäle!$E$15+Kanäle!$F$15+Kanäle!$G$15 -> 0 | I9: 0 | J9: 0 | K9: =Kanäle!$B$15+Kanäle!$C$15+Kanäle!$D$15+Kanäle!$E$15+Kanäle!$F$15+Kanäle!$G$15 -> 0 | L9: 0 | M9: 0 | N9: =Kanäle!$B$15+Kanäle!$C$15+Kanäle!$D$15+Kanäle!$E$15+Kanäle!$F$15+Kanäle!$G$15 -> 0 | O9: =SUM(C9:N9) -> 0
B10: Pay-Per-Click Marketing | C10: 0 | D10: 0 | E10: 0 | O10: =SUM(C10:N10) -> 0
B11: Display Advertising | C11: 0 | D11: 0 | E11: 0 | O11: =SUM(C11:N11) -> 0
B12: Retargeting | C12: 0 | D12: 0 | E12: 0 | O12: =SUM(C12:N12) -> 0
B13: Social Media | C13: 0 | D13: 0 | E13: 0 | O13: =SUM(C13:N13) -> 0
B14: Newsletter | C14: 0 | D14: 0 | E14: 0 | F14: =Kanäle!$B$38+Kanäle!$C$38+Kanäle!$E$38 -> 51 | G14: =Kanäle!$B$38+Kanäle!$C$38+Kanäle!$E$38 -> 51 | H14: =Kanäle!$B$38+Kanäle!$C$38+Kanäle!$E$38 -> 51 | I14: =Kanäle!$B$38+Kanäle!$C$38+Kanäle!$E$38 -> 51 | J14: =Kanäle!$B$38+Kanäle!$C$38+Kanäle!$E$38 -> 51 | K14: =Kanäle!$B$38+Kanäle!$C$38+Kanäle!$E$38 -> 51 | L14: =Kanäle!$B$38+Kanäle!$C$38+Kanäle!$E$38 -> 51 | M14: =Kanäle!$B$38+Kanäle!$C$38+Kanäle!$E$38 -> 51 | N14: =Kanäle!$B$38+Kanäle!$C$38+Kanäle!$E$38 -> 51 | O14: =SUM(C14:N14) -> 459
B15: TypeIn | C15: 0 | D15: 0 | E15: 0 | F15: 0 | G15: 0 | H15: 0 | I15: 0 | J15: 0 | K15: 0 | L15: 0 | M15: 0 | N15: 0 | O15: =SUM(C15:N15) -> 0
B16: Investment / Consulting | C16: =SUM(C17:C18) -> 0 | D16: =SUM(D17:D18) -> 0 | E16: =SUM(E17:E18) -> 0 | F16: =SUM(F17:F18) -> 0 | G16: =SUM(G17:G18) -> 0 | H16: =SUM(H17:H18) -> 0 | I16: =SUM(I17:I18) -> 0 | J16: =SUM(J17:J18) -> 0 | ... N16: =SUM(N17:N18) -> 0 | O16: =SUM(C16:N16) -> 0
B17: Web Development | C17: 0 | D17: 0 | E17: =Invest!$B$3+Invest!$C$3+Kanäle!$B$42+Kanäle!$C$42 -> 0 | F17: 0 | G17: 0 | I17: 0 | J17: 0 | K17: 0 | L17: 0 | M17: 0 | N17: 0 | O17: =SUM(C17:N17) -> 0
B18: Umsetzung | C18: 0 | D18: 0 | E18: =Invest!$B$9+Invest!$C$9 -> 0 | F18: =Invest!$B$9+Invest!$C$9 -> 0 | G18: =Invest!$B$9+Invest!$C$9 -> 0 | H18: =Invest!$B$9+Invest!$C$9 -> 0 | I18: 0 | J18: 0 | K18: 0 | L18: 0 | M18: 0 | N18: 0 | O18: =SUM(C18:N18) -> 0
B19: TOTALS | C19: =SUM(C6+C16) -> 0 | D19: =SUM(D6+D16) -> 0 | E19: =SUM(E6+E16) -> 0 | F19: =SUM(F6+F16) -> 51 | G19: =SUM(G6+G16) -> 51 | H19: =SUM(H6+H16) -> 51 | I19: =SUM(I6+I16) -> 51 | J19: =SUM(J6+J16) -> 51 | ... N19: =SUM(N6+N16) -> 5051 | O19: =SUM(C19:N19) -> 15459
B22: 2023 | C22: Q1 | F22: Q2 | I22: Q3 | L22: Q4 | O22: FISCAL YEAR TOTALS
C23: JAN | D23: FEB | E23: MAR | F23: APR | G23: MAY | H23: JUN | I23: JUL | J23: AUG | K23: SEPT | L23: OCT | M23: NOV | N23: DEC
B24: Marketing Maßnahmen | C24: =SUM(C25:C32) -> 20342.7 | D24: =SUM(D25:D32) -> 18101.6 | E24: =SUM(E25:E32) -> 20238.82 | F24: =SUM(F25:F32) -> 19530.1 | G24: =SUM(G25:G32) -> 16738.68 | H24: =SUM(H25:H32) -> 17094.92 | I24: =SUM(I25:I32) -> 19801.4 | J24: =SUM(J25:J32) -> 16160.05 | ... N24: =SUM(N25:N32) -> 23583.8 | O24: =SUM(C24:N24) -> 224025.85
B25: SEO - Offpage | C25: 5555 | D25: 2510 | E25: 2510 | F25: 2510 | G25: 0 | H25: 449.25 | I25: 149.75 | J25: 149.75 | K25: 149.75 | L25: 149.75 | M25: 149.75 | N25: 149.75 | O25: 14432.75
B26: Content+SEO | C26: 0 | D26: 0 | E26: 0 | F26: =Kanäle!$D$11+Kanäle!$E$11 -> 0 | G26: =Kanäle!$D$11+Kanäle!$E$11 -> 0 | H26: =Kanäle!$D$11+Kanäle!$E$11 -> 0 | I26: =Kanäle!$D$11+Kanäle!$E$11 -> 0 | J26: =Kanäle!$D$11+Kanäle!$E$11 -> 0 | K26: =Kanäle!$D$11+Kanäle!$E$11 -> 0 | L26: =Kanäle!$D$11+Kanäle!$E$11 -> 0 | M26: =Kanäle!$D$11+Kanäle!$E$11 -> 0 | N26: =Kanäle!$D$11+Kanäle!$E$11 -> 0 | O26: =SUM(C26:N26) -> 0
B27: Content Marketing | C27: 0 | D27: 0 | E27: 372.45 | F27: 124.15 | G27: 124.15 | H27: 124.15 | I27: 3228 | J27: 0 | K27: 568 | L27: 0 | M27: 0 | N27: 0 | O27: 4540.9
B28: Pay-Per-Click Marketing | C28: 9111.7 | D28: 9915.6 | E28: 11271.23 | F28: 11083.57 | G28: 10802.15 | H28: 10709.14 | I28: 10611.27 | J28: 10197.92 | K28: 11763.51 | L28: 10651.41 | M28: 10771.18 | N28: 15418.47 | O28: 132307.15
B29: Display Advertising | C29: 4500 | D29: 4500 | E29: 4500 | F29: =Kanäle!$C$24+Kanäle!$D$24+Kanäle!$E$24 -> 4500 | G29: =Kanäle!$C$24+Kanäle!$D$24+Kanäle!$E$24 -> 4500 | H29: =Kanäle!$C$24+Kanäle!$D$24+Kanäle!$E$24 -> 4500 | I29: =Kanäle!$C$24+Kanäle!$D$24+Kanäle!$E$24 -> 4500 | J29: =Kanäle!$C$24+Kanäle!$D$24+Kanäle!$E$24 -> 4500 | K29: =Kanäle!$C$24+Kanäle!$D$24+Kanäle!$E$24 -> 4500 | L29: =Kanäle!$C$24+Kanäle!$D$24+Kanäle!$E$24 -> 4500 | M29: =Kanäle!$C$24+Kanäle!$D$24+Kanäle!$E$24 -> 4500 | N29: =Kanäle!$C$24+Kanäle!$D$24+Kanäle!$E$24 -> 4500 | O29: =SUM(C29:N29) -> 54000
B30: Retargeting | C30: 1125 | D30: 1125 | E30: 1125 | F30: =Kanäle!$B$29 -> 1125 | G30: =Kanäle!$B$29 -> 1125 | H30: =Kanäle!$B$29 -> 1125 | I30: =Kanäle!$B$29 -> 1125 | J30: =Kanäle!$B$29 -> 1125 | K30: =Kanäle!$B$29 -> 1125 | L30: =Kanäle!$B$29 -> 1125 | M30: =Kanäle!$B$29 -> 1125 | N30: =Kanäle!$B$29 -> 1125 | O30: =SUM(C30:N30) -> 13500
B31: Social Media | C31: 0 | D31: 0 | E31: 409.14 | F31: 136.38 | G31: 136.38 | H31: 136.38 | I31: 136.38 | J31: 136.38 | K31: 136.38 | L31: 929.67 | M31: 136.38 | N31: 2339.58 | O31: 4633.05
B32: Newsletter | C32: 51 | D32: 51 | E32: 51 | F32: =Kanäle!$B$38+Kanäle!$C$38+Kanäle!$E$38 -> 51 | G32: =Kanäle!$B$38+Kanäle!$C$38+Kanäle!$E$38 -> 51 | H32: =Kanäle!$B$38+Kanäle!$C$38+Kanäle!$E$38 -> 51 | I32: =Kanäle!$B$38+Kanäle!$C$38+Kanäle!$E$38 -> 51 | J32: =Kanäle!$B$38+Kanäle!$C$38+Kanäle!$E$38 -> 51 | K32: =Kanäle!$B$38+Kanäle!$C$38+Kanäle!$E$38 -> 51 | L32: =Kanäle!$B$38+Kanäle!$C$38+Kanäle!$E$38 -> 51 | M32: =Kanäle!$B$38+Kanäle!$C$38+Kanäle!$E$38 -> 51 | N32: =Kanäle!$B$38+Kanäle!$C$38+Kanäle!$E$38 -> 51 | O32: =SUM(C32:N32) -> 612
B33: TypeIn | C33: 0 | D33: 0 | E33: 0 | F33: 0 | G33: 0 | H33: 0 | I33: 0 | J33: 0 | K33: 0 | L33: 0 | M33: 0 | N33: 0 | O33: =SUM(C33:N33) -> 0
B34: Investment / Organisation / Consulting | C34: 0 | D34: 195 | E34: 688 | F34: 0 | G34: 468 | H34: 0 | I34: 1044 | J34: 0 | K34: 0 | L34: 0 | M34: 0 | N34: 0 | O34: 2395
B35: Web Development | C35: 2500 | F35: =Kanäle!$B$42+Kanäle!$C$42+Invest!$D$3 -> 0 | I35: =Kanäle!$B$42+Kanäle!$C$42+Invest!$D$3 -> 0 | L35: =Kanäle!$B$42+Kanäle!$C$42+Invest!$D$3 -> 0 | O35: =SUM(C35:N35) -> 2500
B36: Beratung | E36: =Invest!$B$9+Invest!$C$9 -> 0 | F36: =Invest!$B$9+Invest!$C$9 -> 0 | G36: =Invest!$B$9+Invest!$C$9 -> 0 | H36: =Invest!$B$9+Invest!$C$9 -> 0 | I36: =Invest!$B$9+Invest!$C$9 -> 0 | J36: =Invest!$B$9+Invest!$C$9 -> 0 | K36: =Invest!$B$9+Invest!$C$9 -> 0 | L36: =Invest!$B$9+Invest!$C$9 -> 0 | ... N36: =Invest!$B$9+Invest!$C$9 -> 0 | O36: =SUM(C36:N36) -> 0
B37: TOTALS | C37: =SUM(C24+C34) -> 20342.7 | D37: =SUM(D24+D34) -> 18296.6 | E37: =SUM(E24+E34) -> 20926.82 | F37: =SUM(F24+F34) -> 19530.1 | G37: =SUM(G24+G34) -> 17206.68 | H37: =SUM(H24+H34) -> 17094.92 | I37: =SUM(I24+I34) -> 20845.4 | J37: =SUM(J24+J34) -> 16160.05 | ... N37: =SUM(N24+N34) -> 23583.8 | O37: =SUM(C37:N37) -> 226420.85
B40: 2024 | C40: Q1 | F40: Q2 | I40: Q3 | L40: Q4 | O40: FISCAL YEAR TOTALS
C41: JAN | D41: FEB | E41: MAR | F41: APR | G41: MAY | H41: JUN | I41: JUL | J41: AUG | K41: SEPT | L41: OCT | M41: NOV | N41: DEC
B42: Marketing Maßnahmen | C42: =SUM(C43:C50) -> 17403.8 | D42: =SUM(D43:D50) -> 18080.18 | E42: =SUM(E43:E50) -> 18351.42 | F42: =SUM(F43:F50) -> 22781.92 | G42: =SUM(G43:G50) -> 21593.28 | H42: =SUM(H43:H50) -> 45644.91 | I42: =SUM(I43:I50) -> 22143.49 | J42: =SUM(J43:J50) -> 22143.73 | ... N42: =SUM(N43:N50) -> 23782.82 | O42: =SUM(C42:N42) -> 288472.17
B43: SEO - Offpage | C43: 149.75 | D43: 149.75 | E43: 149.75 | F43: 0 | G43: 0 | H43: 0 | I43: 0 | J43: 299.5 | K43: 215.64 | L43: 59.9 | M43: 59.9 | N43: 275.54 | O43: 1359.73
B44: Content+SEO | C44: 0 | D44: 0 | E44: 0 | F44: =Kanäle!$D$11+Kanäle!$E$11 -> 0 | G44: =Kanäle!$D$11+Kanäle!$E$11 -> 0 | H44: =Kanäle!$D$11+Kanäle!$E$11 -> 0 | I44: =Kanäle!$D$11+Kanäle!$E$11 -> 0 | J44: =Kanäle!$D$11+Kanäle!$E$11 -> 0 | K44: =Kanäle!$D$11+Kanäle!$E$11 -> 0 | L44: =Kanäle!$D$11+Kanäle!$E$11 -> 0 | M44: =Kanäle!$D$11+Kanäle!$E$11 -> 0 | N44: =Kanäle!$D$11+Kanäle!$E$11 -> 0 | O44: =SUM(C44:N44) -> 0
B45: Content Marketing | C45: 0 | D45: 0 | E45: 0 | F45: 0 | G45: 0 | H45: 0 | I45: 1614 | J45: 1614 | K45: 0 | L45: 239.29 | M45: 239.29 | N45: 239.29 | O45: 3945.87
...

Sheet Traffic
B1: ONLINE MARKETING TRAFFIC
B4: 2022 | C4: Q1 | F4: Q2 | I4: Q3 | L4: Q4 | O4: VISITORS YEAR TOTALS
C5: JAN | D5: FEB | E5: MAR | F5: APR | G5: MAY | H5: JUN | I5: JUL | J5: AUG | K5: SEPT | L5: OCT | M5: NOV | N5: DEC
B6: Marketing Maßnahmen | C6: =SUM(C7:C15) -> 0 | D6: =SUM(D7:D15) -> 0 | E6: =SUM(E7:E15) -> 2100 | F6: =SUM(F7:F15) -> 2901.25 | G6: =SUM(G7:G15) -> 3640.3125 | H6: =SUM(H7:H15) -> 4564.1406 | I6: =SUM(I7:I15) -> 5718.9258 | J6: =SUM(J7:J15) -> 7162.4072 | ... N6: =SUM(N7:N15) -> 17565.623 | O6: =SUM(C6:N6) -> 77883.116
B7: SEO | C7: 0 | D7: 0 | E7: 1000 | F7: =E7*1.25 -> 1250 | G7: =F7*1.25 -> 1562.5 | H7: =G7*1.25 -> 1953.125 | I7: =H7*1.25 -> 2441.4062 | J7: =I7*1.25 -> 3051.7578 | K7: =J7*1.25 -> 3814.6973 | L7: =K7*1.25 -> 4768.3716 | M7: =L7*1.25 -> 5960.4645 | N7: =M7*1.25 -> 7450.5806 | O7: =SUM(C7:N7) -> 33252.903
C8: 0 | D8: 0 | E8: 0 | F8: 0 | G8: 0 | H8: 0 | I8: 0 | J8: 0 | K8: 0 | L8: 0 | M8: 0 | N8: 0 | O8: =SUM(C8:N8) -> 0
B9: Content Marketing | C9: 0 | D9: 0 | E9: 1000 | F9: =E9*1.25 -> 1250 | G9: =F9*1.25 -> 1562.5 | H9: =G9*1.25 -> 1953.125 | I9: =H9*1.25 -> 2441.4062 | J9: =I9*1.25 -> 3051.7578 | K9: =J9*1.25 -> 3814.6973 | L9: =K9*1.25 -> 4768.3716 | M9: =L9*1.25 -> 5960.4645 | N9: =M9*1.25 -> 7450.5806 | O9: =SUM(C9:N9) -> 33252.903
B10: Pay-Per-Click Marketing | C10: 0 | D10: 0 | E10: 0 | O10: =SUM(C10:N10) -> 0
B11: Display Advertising | C11: 0 | D11: 0 | E11: 0 | O11: =SUM(C11:N11) -> 0
B12: Retargeting | C12: 0 | D12: 0 | E12: 0 | O12: =SUM(C12:N12) -> 0
B13: Social Media | C13: 0 | D13: 0 | E13: 100 | F13: =E13*1.25 -> 125 | G13: =F13*1.25 -> 156.25 | H13: =G13*1.25 -> 195.3125 | I13: =H13*1.25 -> 244.14062 | J13: =I13*1.25 -> 305.17578 | K13: =J13*1.25 -> 381.46973 | L13: =K13*1.25 -> 476.83716 | M13: =L13*1.25 -> 596.04645 | N13: =M13*1.25 -> 745.05806 | O13: =SUM(C13:N13) -> 3325.2903
B14: Newsletter | C14: 0 | D14: 0 | E14: 0 | F14: =E14+(F9*0.01) -> 12.5 | G14: =F14+(G9*0.01) -> 28.125 | H14: =G14+(H9*0.01) -> 47.65625 | I14: =H14+(I9*0.01) -> 72.070312 | J14: =I14+(J9*0.01) -> 102.58789 | K14: =J14+(K9*0.01) -> 140.73486 | L14: =K14+(L9*0.01) -> 188.41858 | M14: =L14+(M9*0.01) -> 248.02322 | N14: =M14+(N9*0.01) -> 322.52903 | O14: =SUM(C14:N14) -> 1162.6451
B15: TypeIn | C15: 0 | D15: 0 | E15: 0 | F15: =SUM(F7:F14)*0.1 -> 263.75 | G15: =SUM(G7:G14)*0.1 -> 330.9375 | H15: =SUM(H7:H14)*0.1 -> 414.92188 | I15: =SUM(I7:I14)*0.1 -> 519.90234 | J15: =SUM(J7:J14)*0.1 -> 651.12793 | K15: =SUM(K7:K14)*0.1 -> 815.15991 | L15: =SUM(L7:L14)*0.1 -> 1020.1999 | M15: =SUM(M7:M14)*0.1 -> 1276.4999 | N15: =SUM(N7:N14)*0.1 -> 1596.8748 | O15: =SUM(C15:N15) -> 6889.3741
B16: TOTALS | C16: =SUM(C7:C15) -> 0 | D16: =SUM(D7:D15) -> 0 | E16: =SUM(E7:E15) -> 2100 | F16: =SUM(F7:F15) -> 2901.25 | G16: =SUM(G7:G15) -> 3640.3125 | H16: =SUM(H7:H15) -> 4564.1406 | I16: =SUM(I7:I15) -> 5718.9258 | J16: =SUM(J7:J15) -> 7162.4072 | ... O16: =SUM(O7:O15) -> 77883.116
B22: 2023 | C22: Q1 | F22: Q2 | I22: Q3 | L22: Q4 | O22: VISITORS YEAR TOTALS
C23: JAN | D23: FEB | E23: MAR | F23: APR | G23: MAY | H23: JUN | I23: JUL | J23: AUG | K23: SEPT | L23: OCT | M23: NOV | N23: DEC
B24: Marketing Maßnahmen | C24: =SUM(C25:C33) -> 31056.707 | D24: =SUM(D25:D33) -> 32207.943 | E24: =SUM(E25:E33) -> 37033.347 | F24: =SUM(F25:F33) -> 38612.834 | G24: =SUM(G25:G33) -> 40257.314 | H24: =SUM(H25:H33) -> 45608.785 | I24: =SUM(I25:I33) -> 47750.447 | J24: =SUM(J25:J33) -> 49996.819 | ... N24: =SUM(N25:N33) -> 68623.754 | O24: =SUM(C24:N24) -> 567793.04
B25: SEO | C25: =N7*1.1 -> 8195.6387 | D25: =C25*1.1 -> 9015.2025 | E25: =D25*1.1 -> 9916.7228 | F25: =E25*1.1 -> 10908.395 | G25: =F25*1.1 -> 11999.235 | H25: =G25*1.1 -> 13199.158 | I25: =H25*1.1 -> 14519.074 | J25: =I25*1.1 -> 15970.981 | K25: =J25*1.1 -> 17568.079 | ... N25: =M25*1.1 -> 23383.114 | O25: =SUM(C25:N25) -> 175257.86
O26: =SUM(C26:N26) -> 0
B27: Content Marketing | C27: =N9-500 -> 6950.5806 | D27: =C27-500 -> 6450.5806 | E27: =D27-500+3000 -> 8950.5806 | F27: =E27-500 -> 8450.5806 | G27: =F27-500 -> 7950.5806 | H27: =G27-500+3000 -> 10450.581 | I27: =H27-500 -> 9950.5806 | J27: =I27-500 -> 9450.5806 | K27: =J27-500+3000 -> 11950.581 | L27: =K27-500 -> 11450.581 | M27: =L27-500 -> 10950.581 | N27: =M27-500+3000 -> 13450.581 | O27: =SUM(C27:N27) -> 116406.97
B28: Pay-Per-Click Marketing | C28: =Kanäle!$E$20+Kanäle!$F$20 -> 4500 | D28: =Kanäle!$E$20+Kanäle!$F$20 -> 4500 | E28: =Kanäle!$E$20+Kanäle!$F$20 -> 4500 | F28: =Kanäle!$E$20+Kanäle!$F$20 -> 4500 | G28: =Kanäle!$E$20+Kanäle!$F$20 -> 4500 | H28: =Kanäle!$E$20+Kanäle!$F$20 -> 4500 | I28: =Kanäle!$E$20+Kanäle!$F$20 -> 4500 | J28: =Kanäle!$E$20+Kanäle!$F$20 -> 4500 | ... N28: =Kanäle!$E$20+Kanäle!$F$20 -> 4500 | O28: =SUM(C28:N28) -> 54000
B29: Display Advertising | C29: =Kanäle!$C$25+Kanäle!$D$25 -> 4500 | D29: =Kanäle!$C$25+Kanäle!$D$25 -> 4500 | E29: =Kanäle!$C$25+Kanäle!$D$25 -> 4500 | F29: =Kanäle!$C$25+Kanäle!$D$25 -> 4500 | G29: =Kanäle!$C$25+Kanäle!$D$25 -> 4500 | H29: =Kanäle!$C$25+Kanäle!$D$25 -> 4500 | I29: =Kanäle!$C$25+Kanäle!$D$25 -> 4500 | J29: =Kanäle!$C$25+Kanäle!$D$25 -> 4500 | ... N29: =Kanäle!$C$25+Kanäle!$D$25 -> 4500 | O29: =SUM(C29:N29) -> 54000
B30: Retargeting | C30: =Kanäle!$B$30 -> 2250 | D30: =Kanäle!$B$30 -> 2250 | E30: =Kanäle!$B$30 -> 2250 | F30: =Kanäle!$B$30 -> 2250 | G30: =Kanäle!$B$30 -> 2250 | H30: =Kanäle!$B$30 -> 2250 | I30: =Kanäle!$B$30 -> 2250 | J30: =Kanäle!$B$30 -> 2250 | ... N30: =Kanäle!$B$30 -> 2250 | O30: =SUM(C30:N30) -> 27000
B31: Social Media | C31: =N13*1.1 -> 819.56387 | D31: =C31*1.1 -> 901.52025 | E31: =D31*1.1 -> 991.67228 | F31: =E31*1.1 -> 1090.8395 | G31: =F31*1.1 -> 1199.9235 | H31: =G31*1.1 -> 1319.9158 | I31: =H31*1.1 -> 1451.9074 | J31: =I31*1.1 -> 1597.0981 | K31: =J31*1.1 -> 1756.8079 | ... N31: =M31*1.1 -> 2338.3114 | O31: =SUM(C31:N31) -> 17525.786
B32: Newsletter | C32: =N14+(C27*0.1) -> 1017.5871 | D32: =C32+(D27*0.1) -> 1662.6451 | E32: =D32+(E27*0.1) -> 2557.7032 | F32: =E32+(F27*0.1) -> 3402.7613 | G32: =F32+(G27*0.1) -> 4197.8193 | H32: =G32+(H27*0.1) -> 5242.8774 | I32: =H32+(I27*0.1) -> 6237.9354 | J32: =I32+(J27*0.1) -> 7182.9935 | K32: =J32+(K27*0.1) -> 8378.0516 | ... N32: =M32+(N27*0.1) -> 11963.226 | O32: =SUM(C32:N32) -> 71984.877
B33: TypeIn | C33: =SUM(C25:C32)*0.1 -> 2823.337 | D33: =SUM(D25:D32)*0.1 -> 2927.9949 | E33: =SUM(E25:E32)*0.1 -> 3366.6679 | F33: =SUM(F25:F32)*0.1 -> 3510.2576 | G33: =SUM(G25:G32)*0.1 -> 3659.7558 | H33: =SUM(H25:H32)*0.1 -> 4146.2532 | I33: =SUM(I25:I32)*0.1 -> 4340.9497 | J33: =SUM(J25:J32)*0.1 -> 4545.1653 | ... N33: =SUM(N25:N32)*0.1 -> 6238.5231 | O33: =SUM(C33:N33) -> 51617.549
B34: TOTALS | C34: =SUM(C25:C33) -> 31056.707 | D34: =SUM(D25:D33) -> 32207.943 | E34: =SUM(E25:E33) -> 37033.347 | F34: =SUM(F25:F33) -> 38612.834 | G34: =SUM(G25:G33) -> 40257.314 | H34: =SUM(H25:H33) -> 45608.785 | I34: =SUM(I25:I33) -> 47750.447 | J34: =SUM(J25:J33) -> 49996.819 | ... O34: =SUM(O25:O33) -> 567793.04
B40: 2024 | C40: Q1 | F40: Q2 | I40: Q3 | L40: Q4 | O40: VISITORS YEAR TOTALS
C41: JAN | D41: FEB | E41: MAR | F41: APR | G41: MAY | H41: JUN | I41: JUL | J41: AUG | K41: SEPT | L41: OCT | M41: NOV | N41: DEC
B42: Marketing Maßnahmen | C42: =SUM(C43:C51) -> 72798.318 | D42: =SUM(D43:D51) -> 76447.239 | E42: =SUM(E43:E51) -> 83954.095 | F42: =SUM(F43:F51) -> 88417.181 | G42: =SUM(G43:G51) -> 93167.618 | H42: =SUM(H43:H51) -> 101869.64 | I42: =SUM(I43:I51) -> 107630.91 | J42: =SUM(J43:J51) -> 113792.86 | ... N42: =SUM(N43:N51) -> 151679.8 | O42: =SUM(C42:N42) -> 1284705.9
B43: SEO | C43: =N25*1.1 -> 25721.425 | D43: =C43*1.1 -> 28293.567 | E43: =D43*1.1 -> 31122.924 | F43: =E43*1.1 -> 34235.217 | G43: =F43*1.1 -> 37658.738 | H43: =G43*1.1 -> 41424.612 | I43: =H43*1.1 -> 45567.073 | J43: =I43*1.1 -> 50123.781 | K43: =J43*1.1 -> 55136.159 | ... N43: =M43*1.1 -> 73386.227 | O43: =SUM(C43:N43) -> 550034.25
O44: =SUM(C44:N44) -> 0
B45: Content Marketing | C45: =N27-500 -> 12950.581 | D45: =C45-500 -> 12450.581 | E45: =D45-500+3000 -> 14950.581 | F45: =E45-500 -> 14450.581 | G45: =F45-500 -> 13950.581 | H45: =G45-500+3000 -> 16450.581 | I45: =H45-500 -> 15950.581 | J45: =I45-500 -> 15450.581 | K45: =J45-500+3000 -> 17950.581 | L45: =K45-500 -> 17450.581 | M45: =L45-500 -> 16950.581 | N45: =M45-500+3000 -> 19450.581 | O45: =SUM(C45:N45) -> 188406.97
B46: Pay-Per-Click Marketing | C46: =Kanäle!$E$20+Kanäle!$F$20 -> 4500 | D46: =Kanäle!$E$20+Kanäle!$F$20 -> 4500 | E46: =Kanäle!$E$20+Kanäle!$F$20 -> 4500 | F46: =Kanäle!$E$20+Kanäle!$F$20 -> 4500 | G46: =Kanäle!$E$20+Kanäle!$F$20 -> 4500 | H46: =Kanäle!$E$20+Kanäle!$F$20 -> 4500 | I46: =Kanäle!$E$20+Kanäle!$F$20 -> 4500 | J46: =Kanäle!$E$20+Kanäle!$F$20 -> 4500 | ... N46: =Kanäle!$E$20+Kanäle!$F$20 -> 4500 | O46: =SUM(C46:N46) -> 54000
B47: Display Advertising | C47: =Kanäle!$C$25+Kanäle!$D$25 -> 4500 | D47: =Kanäle!$C$25+Kanäle!$D$25 -> 4500 | E47: =Kanäle!$C$25+Kanäle!$D$25 -> 4500 | F47: =Kanäle!$C$25+Kanäle!$D$25 -> 4500 | G47: =Kanäle!$C$25+Kanäle!$D$25 -> 4500 | H47: =Kanäle!$C$25+Kanäle!$D$25 -> 4500 | I47: =Kanäle!$C$25+Kanäle!$D$25 -> 4500 | J47: =Kanäle!$C$25+Kanäle!$D$25 -> 4500 | ... N47: =Kanäle!$C$25+Kanäle!$D$25 -> 4500 | O47: =SUM(C47:N47) -> 54000
B48: Retargeting | C48: =Kanäle!$B$30 -> 2250 | D48: =Kanäle!$B$30 -> 2250 | E48: =Kanäle!$B$30 -> 2250 | F48: =Kanäle!$B$30 -> 2250 | G48: =Kanäle!$B$30 -> 2250 | H48: =Kanäle!$B$30 -> 2250 | I48: =Kanäle!$B$30 -> 2250 | J48: =Kanäle!$B$30 -> 2250 | ... N48: =Kanäle!$B$30 -> 2250 | O48: =SUM(C48:N48) -> 27000
B49: Social Media | C49: 3000 | D49: 3000 | E49: 3000 | F49: 3000 | G49: 3000 | H49: 3000 | I49: 3000 | J49: 3000 | K49: 3000 | L49: 3000 | M49: 3000 | N49: 3000 | O49: =SUM(C49:N49) -> 36000
B50: Newsletter | C50: =N32+(C45*0.1) -> 13258.284 | D50: =C50+(D45*0.1) -> 14503.342 | E50: =D50+(E45*0.1) -> 15998.4 | F50: =E50+(F45*0.1) -> 17443.458 | G50: =F50+(G45*0.1) -> 18838.516 | H50: =G50+(H45*0.1) -> 20483.574 | I50: =H50+(I45*0.1) -> 22078.632 | J50: =I50+(J45*0.1) -> 23623.69 | K50: =J50+(K45*0.1) -> 25418.748 | ... N50: =M50+(N45*0.1) -> 30803.922 | O50: =SUM(C50:N50) -> 258473.24
B51: TypeIn | C51: =SUM(C43:C50)*0.1 -> 6618.0289 | D51: =SUM(D43:D50)*0.1 -> 6949.749 | E51: =SUM(E43:E50)*0.1 -> 7632.1905 | F51: =SUM(F43:F50)*0.1 -> 8037.9255 | G51: =SUM(G43:G50)*0.1 -> 8469.7835 | H51: =SUM(H43:H50)*0.1 -> 9260.8767 | I51: =SUM(I43:I50)*0.1 -> 9784.6286 | J51: =SUM(J43:J50)*0.1 -> 10344.805 | ... N51: =SUM(N43:N50)*0.1 -> 13789.073 | O51: =SUM(C51:N51) -> 116791.45
B52: TOTALS | C52: =SUM(C43:C51) -> 72798.318 | D52: =SUM(D43:D51) -> 76447.239 | E52: =SUM(E43:E51) -> 83954.095 | F52: =SUM(F43:F51) -> 88417.181 | G52: =SUM(G43:G51) -> 93167.618 | H52: =SUM(H43:H51) -> 101869.64 | I52: =SUM(I43:I51) -> 107630.91 | J52: =SUM(J43:J51) -> 113792.86 | ... O52: =SUM(O43:O51) -> 1284705.9

Sheet Umsatz
B1: ONLINE MARKETING UMSATZ
B4: 2022 | C4: Q1 | F4: Q2 | I4: Q3 | L4: Q4 | O4: SALES YEAR TOTALS
C5: JAN | D5: FEB | E5: MAR | F5: APR | G5: MAY | H5: JUN | I5: JUL | J5: AUG | K5: SEPT | L5: OCT | M5: NOV | N5: DEC
B6: Marketing Maßnahmen | C6: =SUM(C7:C15) -> 0 | D6: =SUM(D7:D15) -> 0 | E6: =SUM(E7:E15) -> 14200 | F6: =SUM(F7:F15) -> 19282.5 | G6: =SUM(G7:G15) -> 24210.625 | H6: =SUM(H7:H15) -> 30370.781 | I6: =SUM(I7:I15) -> 38363.945 | J6: =SUM(J7:J15) -> 48062.432 | ... N6: =SUM(N7:N15) -> 117959.73 | O6: =SUM(C6:N6) -> 522256.75
B7: SEO | C7: =(Traffic!C7*Kanäle!$C$5)*Kanäle!$C$2 -> 0 | D7: =(Traffic!D7*Kanäle!$C$5)*Kanäle!$C$2 -> 0 | E7: =(Traffic!E7*Kanäle!$C$5)*Kanäle!$C$2 -> 6000 | F7: =(Traffic!F7*Kanäle!$C$5)*Kanäle!$C$2 -> 7500 | G7: =(Traffic!G7*Kanäle!$C$5)*Kanäle!$C$2 -> 9375 | H7: =(Traffic!H7*Kanäle!$C$5)*Kanäle!$C$2 -> 11718.75 | I7: =(Traffic!I7*Kanäle!$C$5)*Kanäle!$C$2 -> 14648.438 | J7: =(Traffic!J7*Kanäle!$C$5)*Kanäle!$C$2 -> 18310.547 | ... N7: =(Traffic!N7*Kanäle!$C$5)*Kanäle!$C$2 -> 44703.484 | O7: =SUM(C7:N7) -> 199517.42
C8: 0 | D8: 0 | E8: 0 | F8: 0 | G8: 0 | H8: 0 | I8: 0 | J8: 0 | K8: 0 | L8: 0 | M8: 0 | N8: 0 | O8: =SUM(C8:N8) -> 0
B9: Content Marketing | C9: =(Traffic!C9*Kanäle!$C$13)*Kanäle!$C$2 -> 0 | D9: =(Traffic!D9*Kanäle!$C$13)*Kanäle!$C$2 -> 0 | E9: =(Traffic!E9*Kanäle!$C$13)*Kanäle!$C$2 -> 8000 | F9: =(Traffic!F9*Kanäle!$C$13)*Kanäle!$C$2 -> 10000 | G9: =(Traffic!G9*Kanäle!$C$13)*Kanäle!$C$2 -> 12500 | H9: =(Traffic!H9*Kanäle!$C$13)*Kanäle!$C$2 -> 15625 | I9: =(Traffic!I9*Kanäle!$C$13)*Kanäle!$C$2 -> 19531.25 | J9: =(Traffic!J9*Kanäle!$C$13)*Kanäle!$C$2 -> 24414.062 | ... N9: =(Traffic!N9*Kanäle!$C$13)*Kanäle!$C$2 -> 59604.645 | O9: =SUM(C9:N9) -> 266023.22
B10: Pay-Per-Click Marketing | C10: =(Traffic!C10*Kanäle!$C$17)*Kanäle!$C$2 -> 0 | D10: =(Traffic!D10*Kanäle!$C$17)*Kanäle!$C$2 -> 0 | E10: =(Traffic!E10*Kanäle!$C$17)*Kanäle!$C$2 -> 0 | F10: =(Traffic!F10*Kanäle!$C$17)*Kanäle!$C$2 -> 0 | G10: =(Traffic!G10*Kanäle!$C$17)*Kanäle!$C$2 -> 0 | H10: =(Traffic!H10*Kanäle!$C$17)*Kanäle!$C$2 -> 0 | I10: =(Traffic!I10*Kanäle!$C$17)*Kanäle!$C$2 -> 0 | J10: =(Traffic!J10*Kanäle!$C$17)*Kanäle!$C$2 -> 0 | ... N10: =(Traffic!N10*Kanäle!$C$17)*Kanäle!$C$2 -> 0 | O10: =SUM(C10:N10) -> 0
B11: Display Advertising | C11: =(Traffic!C11*Kanäle!$C$22)*Kanäle!$C$2 -> 0 | D11: =(Traffic!D11*Kanäle!$C$22)*Kanäle!$C$2 -> 0 | E11: =(Traffic!E11*Kanäle!$C$22)*Kanäle!$C$2 -> 0 | F11: =(Traffic!F11*Kanäle!$C$22)*Kanäle!$C$2 -> 0 | G11: =(Traffic!G11*Kanäle!$C$22)*Kanäle!$C$2 -> 0 | H11: =(Traffic!H11*Kanäle!$C$22)*Kanäle!$C$2 -> 0 | I11: =(Traffic!I11*Kanäle!$C$22)*Kanäle!$C$2 -> 0 | J11: =(Traffic!J11*Kanäle!$C$22)*Kanäle!$C$2 -> 0 | ... N11: =(Traffic!N11*Kanäle!$C$22)*Kanäle!$C$2 -> 0 | O11: =SUM(C11:N11) -> 0
B12: Retargeting | C12: =(Traffic!C12*Kanäle!$C$27)*Kanäle!$C$2 -> 0 | D12: =(Traffic!D12*Kanäle!$C$27)*Kanäle!$C$2 -> 0 | E12: =(Traffic!E12*Kanäle!$C$27)*Kanäle!$C$2 -> 0 | F12: =(Traffic!F12*Kanäle!$C$27)*Kanäle!$C$2 -> 0 | G12: =(Traffic!G12*Kanäle!$C$27)*Kanäle!$C$2 -> 0 | H12: =(Traffic!H12*Kanäle!$C$27)*Kanäle!$C$2 -> 0 | I12: =(Traffic!I12*Kanäle!$C$27)*Kanäle!$C$2 -> 0 | J12: =(Traffic!J12*Kanäle!$C$27)*Kanäle!$C$2 -> 0 | ... N12: =(Traffic!N12*Kanäle!$C$27)*Kanäle!$C$2 -> 0 | O12: =SUM(C12:N12) -> 0
B13: Social Media | C13: =(Traffic!C13*Kanäle!$C$32)*Kanäle!$C$2 -> 0 | D13: =(Traffic!D13*Kanäle!$C$32)*Kanäle!$C$2 -> 0 | E13: =(Traffic!E13*Kanäle!$C$32)*Kanäle!$C$2 -> 200 | F13: =(Traffic!F13*0.02)*40 -> 100 | G13: =(Traffic!G13*0.02)*40 -> 125 | H13: =(Traffic!H13*0.02)*40 -> 156.25 | I13: =(Traffic!I13*Kanäle!$C$32)*Kanäle!$C$2 -> 488.28125 | J13: =(Traffic!J13*Kanäle!$C$32)*Kanäle!$C$2 -> 610.35156 | K13: =(Traffic!K13*Kanäle!$C$32)*Kanäle!$C$2 -> 762.93945 | L13: =(Traffic!L13*Kanäle!$C$32)*Kanäle!$C$2 -> 953.67432 | M13: =(Traffic!M13*Kanäle!$C$32)*Kanäle!$C$2 -> 1192.0929 | N13: =(Traffic!N13*Kanäle!$C$32)*Kanäle!$C$2 -> 1490.1161 | O13: =SUM(C13:N13) -> 6078.7056
B14: Newsletter | C14: =(Traffic!C14*Kanäle!$C$36)*Kanäle!$C$2 -> 0 | D14: =(Traffic!D14*Kanäle!$C$36)*Kanäle!$C$2 -> 0 | E14: =(Traffic!E14*Kanäle!$C$36)*Kanäle!$C$2 -> 0 | F14: =(Traffic!F14*Kanäle!$C$36)*Kanäle!$C$2 -> 100 | G14: =(Traffic!G14*Kanäle!$C$36)*Kanäle!$C$2 -> 225 | H14: =(Traffic!H14*Kanäle!$C$36)*Kanäle!$C$2 -> 381.25 | I14: =(Traffic!I14*Kanäle!$C$36)*Kanäle!$C$2 -> 576.5625 | J14: =(Traffic!J14*Kanäle!$C$36)*Kanäle!$C$2 -> 820.70312 | ... N14: =(Traffic!N14*Kanäle!$C$36)*Kanäle!$C$2 -> 2580.2322 | O14: =SUM(C14:N14) -> 9301.1612
B15: TypeIn | C15: =(Traffic!C15*Kanäle!$B$2)*Kanäle!$C$2 -> 0 | D15: =(Traffic!D15*Kanäle!$B$2)*Kanäle!$C$2 -> 0 | E15: =(Traffic!E15*Kanäle!$B$2)*Kanäle!$C$2 -> 0 | F15: =(Traffic!F15*Kanäle!$B$2)*Kanäle!$C$2 -> 1582.5 | G15: =(Traffic!G15*Kanäle!$B$2)*Kanäle!$C$2 -> 1985.625 | H15: =(Traffic!H15*Kanäle!$B$2)*Kanäle!$C$2 -> 2489.5312 | I15: =(Traffic!I15*Kanäle!$B$2)*Kanäle!$C$2 -> 3119.4141 | J15: =(Traffic!J15*Kanäle!$B$2)*Kanäle!$C$2 -> 3906.7676 | ... N15: =(Traffic!N15*Kanäle!$B$2)*Kanäle!$C$2 -> 9581.249 | O15: =SUM(C15:N15) -> 41336.245
B16: TOTALS | C16: =SUM(C7:C15) -> 0 | D16: =SUM(D7:D15) -> 0 | E16: =SUM(E7:E15) -> 14200 | F16: =SUM(F7:F15) -> 19282.5 | G16: =SUM(G7:G15) -> 24210.625 | H16: =SUM(H7:H15) -> 30370.781 | I16: =SUM(I7:I15) -> 38363.945 | J16: =SUM(J7:J15) -> 48062.432 | ... O16: =SUM(O7:O15) -> 522256.75
B22: 2023 | C22: Q1 | F22: Q2 | I22: Q3 | L22: Q4 | O22: SALES YEAR
C23: JAN | D23: FEB | E23: MAR | F23: APR | G23: MAY | H23: JUN | I23: JUL | J23: AUG | K23: SEPT | L23: OCT | M23: NOV | N23: DEC | O23: TOTALS
B24: Marketing Maßnahmen | C24: =SUM(C25:C33) -> 221498.32 | D24: =SUM(D25:D33) -> 228368.03 | E24: =SUM(E25:E33) -> 263749.96 | F24: =SUM(F25:F33) -> 273520.33 | G24: =SUM(G25:G33) -> 283540.99 | H24: =SUM(H25:H33) -> 322259.96 | I24: =SUM(I25:I33) -> 335572.08 | J24: =SUM(J25:J33) -> 349359.67 | ... N24: =SUM(N25:N33) -> 475716.89 | O24: =SUM(C24:N24) -> 3983438.8
B25: SEO | C25: =(Traffic!C25*Kanäle!$C$5)*Kanäle!$C$2 -> 49173.832 | D25: =(Traffic!D25*Kanäle!$C$5)*Kanäle!$C$2 -> 54091.215 | E25: =(Traffic!E25*Kanäle!$C$5)*Kanäle!$C$2 -> 59500.337 | F25: =(Traffic!F25*Kanäle!$C$5)*Kanäle!$C$2 -> 65450.37 | G25: =(Traffic!G25*Kanäle!$C$5)*Kanäle!$C$2 -> 71995.407 | H25: =(Traffic!H25*Kanäle!$C$5)*Kanäle!$C$2 -> 79194.948 | I25: =(Traffic!I25*Kanäle!$C$5)*Kanäle!$C$2 -> 87114.443 | J25: =(Traffic!J25*Kanäle!$C$5)*Kanäle!$C$2 -> 95825.887 | ... N25: =(Traffic!N25*Kanäle!$C$5)*Kanäle!$C$2 -> 140298.68 | O25: =SUM(C25:N25) -> 1051547.2
C26: 0 | D26: 0 | E26: 0 | F26: 0 | G26: 0 | H26: 0 | I26: 0 | J26: 0 | K26: 0 | L26: 0 | M26: 0 | N26: 0 | O26: =SUM(C26:N26) -> 0
B27: Content Marketing | C27: =(Traffic!C27*Kanäle!$C$13)*Kanäle!$C$2 -> 55604.645 | D27: =(Traffic!D27*Kanäle!$C$13)*Kanäle!$C$2 -> 51604.645 | E27: =(Traffic!E27*Kanäle!$C$13)*Kanäle!$C$2 -> 71604.645 | F27: =(Traffic!F27*Kanäle!$C$13)*Kanäle!$C$2 -> 67604.645 | G27: =(Traffic!G27*Kanäle!$C$13)*Kanäle!$C$2 -> 63604.645 | H27: =(Traffic!H27*Kanäle!$C$13)*Kanäle!$C$2 -> 83604.645 | I27: =(Traffic!I27*Kanäle!$C$13)*Kanäle!$C$2 -> 79604.645 | J27: =(Traffic!J27*Kanäle!$C$13)*Kanäle!$C$2 -> 75604.645 | ... N27: =(Traffic!N27*Kanäle!$C$13)*Kanäle!$C$2 -> 107604.64 | O27: =SUM(C27:N27) -> 931255.74
B28: Pay-Per-Click Marketing | C28: =(Traffic!C28*Kanäle!$C$17)*Kanäle!$C$2 -> 36000 | D28: =(Traffic!D28*Kanäle!$C$17)*Kanäle!$C$2 -> 36000 | E28: =(Traffic!E28*Kanäle!$C$17)*Kanäle!$C$2 -> 36000 | F28: =(Traffic!F28*Kanäle!$C$17)*Kanäle!$C$2 -> 36000 | G28: =(Traffic!G28*Kanäle!$C$17)*Kanäle!$C$2 -> 36000 | H28: =(Traffic!H28*Kanäle!$C$17)*Kanäle!$C$2 -> 36000 | I28: =(Traffic!I28*Kanäle!$C$17)*Kanäle!$C$2 -> 36000 | J28: =(Traffic!J28*Kanäle!$C$17)*Kanäle!$C$2 -> 36000 | ... N28: =(Traffic!N28*Kanäle!$C$17)*Kanäle!$C$2 -> 36000 | O28: =SUM(C28:N28) -> 432000
B29: Display Advertising | C29: =(Traffic!C29*Kanäle!$C$22)*Kanäle!$C$2 -> 36000 | D29: =(Traffic!D29*Kanäle!$C$22)*Kanäle!$C$2 -> 36000 | E29: =(Traffic!E29*Kanäle!$C$22)*Kanäle!$C$2 -> 36000 | F29: =(Traffic!F29*Kanäle!$C$22)*Kanäle!$C$2 -> 36000 | G29: =(Traffic!G29*Kanäle!$C$22)*Kanäle!$C$2 -> 36000 | H29: =(Traffic!H29*Kanäle!$C$22)*Kanäle!$C$2 -> 36000 | I29: =(Traffic!I29*Kanäle!$C$22)*Kanäle!$C$2 -> 36000 | J29: =(Traffic!J29*Kanäle!$C$22)*Kanäle!$C$2 -> 36000 | ... N29: =(Traffic!N29*Kanäle!$C$22)*Kanäle!$C$2 -> 36000 | O29: =SUM(C29:N29) -> 432000
B30: Retargeting | C30: =(Traffic!C30*Kanäle!$C$27)*Kanäle!$C$2 -> 18000 | D30: =(Traffic!D30*Kanäle!$C$27)*Kanäle!$C$2 -> 18000 | E30: =(Traffic!E30*Kanäle!$C$27)*Kanäle!$C$2 -> 18000 | F30: =(Traffic!F30*Kanäle!$C$27)*Kanäle!$C$2 -> 18000 | G30: =(Traffic!G30*Kanäle!$C$27)*Kanäle!$C$2 -> 18000 | H30: =(Traffic!H30*Kanäle!$C$27)*Kanäle!$C$2 -> 18000 | I30: =(Traffic!I30*Kanäle!$C$27)*Kanäle!$C$2 -> 18000 | J30: =(Traffic!J30*Kanäle!$C$27)*Kanäle!$C$2 -> 18000 | ... N30: =(Traffic!N30*Kanäle!$C$27)*Kanäle!$C$2 -> 18000 | O30: =SUM(C30:N30) -> 216000
B31: Social Media | C31: =(Traffic!C31*Kanäle!$C$32)*Kanäle!$C$2 -> 1639.1277 | D31: =(Traffic!D31*Kanäle!$C$32)*Kanäle!$C$2 -> 1803.0405 | E31: =(Traffic!E31*Kanäle!$C$32)*Kanäle!$C$2 -> 1983.3446 | F31: =(Traffic!F31*Kanäle!$C$32)*Kanäle!$C$2 -> 2181.679 | G31: =(Traffic!G31*Kanäle!$C$32)*Kanäle!$C$2 -> 2399.8469 | H31: =(Traffic!H31*Kanäle!$C$32)*Kanäle!$C$2 -> 2639.8316 | I31: =(Traffic!I31*Kanäle!$C$32)*Kanäle!$C$2 -> 2903.8148 | J31: =(Traffic!J31*Kanäle!$C$32)*Kanäle!$C$2 -> 3194.1962 | ... N31: =(Traffic!N31*Kanäle!$C$32)*Kanäle!$C$2 -> 4676.6227 | O31: =SUM(C31:N31) -> 35051.573
B32: Newsletter | C32: =(Traffic!C32*Kanäle!$C$36)*Kanäle!$C$2 -> 8140.6967 | D32: =(Traffic!D32*Kanäle!$C$36)*Kanäle!$C$2 -> 13301.161 | E32: =(Traffic!E32*Kanäle!$C$36)*Kanäle!$C$2 -> 20461.626 | F32: =(Traffic!F32*Kanäle!$C$36)*Kanäle!$C$2 -> 27222.09 | G32: =(Traffic!G32*Kanäle!$C$36)*Kanäle!$C$2 -> 33582.555 | H32: =(Traffic!H32*Kanäle!$C$36)*Kanäle!$C$2 -> 41943.019 | I32: =(Traffic!I32*Kanäle!$C$36)*Kanäle!$C$2 -> 49903.484 | J32: =(Traffic!J32*Kanäle!$C$36)*Kanäle!$C$2 -> 57463.948 | ... N32: =(Traffic!N32*Kanäle!$C$36)*Kanäle!$C$2 -> 95705.806 | O32: =SUM(C32:N32) -> 575879.02
B33: TypeIn | C33: =(Traffic!C33*Kanäle!$B$2)*Kanäle!$C$2 -> 16940.022 | D33: =(Traffic!D33*Kanäle!$B$2)*Kanäle!$C$2 -> 17567.969 | E33: =(Traffic!E33*Kanäle!$B$2)*Kanäle!$C$2 -> 20200.007 | F33: =(Traffic!F33*Kanäle!$B$2)*Kanäle!$C$2 -> 21061.546 | G33: =(Traffic!G33*Kanäle!$B$2)*Kanäle!$C$2 -> 21958.535 | H33: =(Traffic!H33*Kanäle!$B$2)*Kanäle!$C$2 -> 24877.519 | I33: =(Traffic!I33*Kanäle!$B$2)*Kanäle!$C$2 -> 26045.698 | J33: =(Traffic!J33*Kanäle!$B$2)*Kanäle!$C$2 -> 27270.992 | ... N33: =(Traffic!N33*Kanäle!$B$2)*Kanäle!$C$2 -> 37431.139 | O33: =SUM(C33:N33) -> 309705.3
B34: TOTALS | C34: =SUM(C25:C33) -> 221498.32 | D34: =SUM(D25:D33) -> 228368.03 | E34: =SUM(E25:E33) -> 263749.96 | F34: =SUM(F25:F33) -> 273520.33 | G34: =SUM(G25:G33) -> 283540.99 | H34: =SUM(H25:H33) -> 322259.96 | I34: =SUM(I25:I33) -> 335572.08 | J34: =SUM(J25:J33) -> 349359.67 | ... O34: =SUM(O25:O33) -> 3983438.8
B40: 2024 | C40: Q1 | F40: Q2 | I40: Q3 | L40: Q4 | O40: SALES YEAR TOTALS
C41: JAN | D41: FEB | E41: MAR | F41: APR | G41: MAY | H41: JUN | I41: JUL | J41: AUG | K41: SEPT | L41: OCT | M41: NOV | N41: DEC | O41: TOTALS
B42: Marketing Maßnahmen | C42: =SUM(C43:C51) -> 499707.64 | D42: =SUM(D43:D51) -> 523091.28 | E42: =SUM(E43:E51) -> 576122.53 | F42: =SUM(F43:F51) -> 604791.16 | G42: =SUM(G43:G51) -> 635083.9 | H42: =SUM(H43:H51) -> 695586.17 | I42: =SUM(I43:I51) -> 732343.91 | J42: =SUM(J43:J51) -> 771405.68 | ... N42: =SUM(N43:N51) -> 1021087.8 | O42: =SUM(C42:N42) -> 8727995.8
B43: SEO | C43: =(Traffic!C43*Kanäle!$C$5)*Kanäle!$C$2 -> 154328.55 | D43: =(Traffic!D43*Kanäle!$C$5)*Kanäle!$C$2 -> 169761.4 | E43: =(Traffic!E43*Kanäle!$C$5)*Kanäle!$C$2 -> 186737.54 | F43: =(Traffic!F43*Kanäle!$C$5)*Kanäle!$C$2 -> 205411.3 | G43: =(Traffic!G43*Kanäle!$C$5)*Kanäle!$C$2 -> 225952.43 | H43: =(Traffic!H43*Kanäle!$C$5)*Kanäle!$C$2 -> 248547.67 | I43: =(Traffic!I43*Kanäle!$C$5)*Kanäle!$C$2 -> 273402.44 | J43: =(Traffic!J43*Kanäle!$C$5)*Kanäle!$C$2 -> 300742.68 | ... N43: =(Traffic!N43*Kanäle!$C$5)*Kanäle!$C$2 -> 440317.36 | O43: =SUM(C43:N43) -> 3300205.5
C44: 0 | D44: 0 | E44: 0 | F44: 0 | G44: 0 | H44: 0 | I44: 0 | J44: 0 | K44: 0 | L44: 0 | M44: 0 | N44: 0 | O44: =SUM(C44:N44) -> 0
B45: Content Marketing | C45: =(Traffic!C45*Kanäle!$C$13)*Kanäle!$C$2 -> 103604.64 | D45: =(Traffic!D45*Kanäle!$C$13)*Kanäle!$C$2 -> 99604.645 | E45: =(Traffic!E45*Kanäle!$C$13)*Kanäle!$C$2 -> 119604.64 | F45: =(Traffic!F45*Kanäle!$C$13)*Kanäle!$C$2 -> 115604.64 | G45: =(Traffic!G45*Kanäle!$C$13)*Kanäle!$C$2 -> 111604.64 | H45: =(Traffic!H45*Kanäle!$C$13)*Kanäle!$C$2 -> 131604.64 | I45: =(Traffic!I45*Kanäle!$C$13)*Kanäle!$C$2 -> 127604.64 | J45: =(Traffic!J45*Kanäle!$C$13)*Kanäle!$C$2 -> 123604.64 | ... N45: =(Traffic!N45*Kanäle!$C$13)*Kanäle!$C$2 -> 155604.64 | O45: =SUM(C45:N45) -> 1507255.7
B46: Pay-Per-Click Marketing | C46: =(Traffic!C46*Kanäle!$C$17)*Kanäle!$C$2 -> 36000 | D46: =(Traffic!D46*Kanäle!$C$17)*Kanäle!$C$2 -> 36000 | E46: =(Traffic!E46*Kanäle!$C$17)*Kanäle!$C$2 -> 36000 | F46: =(Traffic!F46*Kanäle!$C$17)*Kanäle!$C$2 -> 36000 | G46: =(Traffic!G46*Kanäle!$C$17)*Kanäle!$C$2 -> 36000 | H46: =(Traffic!H46*Kanäle!$C$17)*Kanäle!$C$2 -> 36000 | I46: =(Traffic!I46*Kanäle!$C$17)*Kanäle!$C$2 -> 36000 | J46: =(Traffic!J46*Kanäle!$C$17)*Kanäle!$C$2 -> 36000 | ... N46: =(Traffic!N46*Kanäle!$C$17)*Kanäle!$C$2 -> 36000 | O46: =SUM(C46:N46) -> 432000
B47: Display Advertising | C47: =(Traffic!C47*Kanäle!$C$22)*Kanäle!$C$2 -> 36000 | D47: =(Traffic!D47*Kanäle!$C$22)*Kanäle!$C$2 -> 36000 | E47: =(Traffic!E47*Kanäle!$C$22)*Kanäle!$C$2 -> 36000 | F47: =(Traffic!F47*Kanäle!$C$22)*Kanäle!$C$2 -> 36000 | G47: =(Traffic!G47*Kanäle!$C$22)*Kanäle!$C$2 -> 36000 | H47: =(Traffic!H47*Kanäle!$C$22)*Kanäle!$C$2 -> 36000 | I47: =(Traffic!I47*Kanäle!$C$22)*Kanäle!$C$2 -> 36000 | J47: =(Traffic!J47*Kanäle!$C$22)*Kanäle!$C$2 -> 36000 | ... N47: =(Traffic!N47*Kanäle!$C$22)*Kanäle!$C$2 -> 36000 | O47: =SUM(C47:N47) -> 432000
B48: Retargeting | C48: =(Traffic!C48*Kanäle!$C$27)*Kanäle!$C$2 -> 18000 | D48: =(Traffic!D48*Kanäle!$C$27)*Kanäle!$C$2 -> 18000 | E48: =(Traffic!E48*Kanäle!$C$27)*Kanäle!$C$2 -> 18000 | F48: =(Traffic!F48*Kanäle!$C$27)*Kanäle!$C$2 -> 18000 | G48: =(Traffic!G48*Kanäle!$C$27)*Kanäle!$C$2 -> 18000 | H48: =(Traffic!H48*Kanäle!$C$27)*Kanäle!$C$2 -> 18000 | I48: =(Traffic!I48*Kanäle!$C$27)*Kanäle!$C$2 -> 18000 | J48: =(Traffic!J48*Kanäle!$C$27)*Kanäle!$C$2 -> 18000 | ... N48: =(Traffic!N48*Kanäle!$C$27)*Kanäle!$C$2 -> 18000 | O48: =SUM(C48:N48) -> 216000
B49: Social Media | C49: =(Traffic!C49*Kanäle!$C$32)*Kanäle!$C$2 -> 6000 | D49: =(Traffic!D49*Kanäle!$C$32)*Kanäle!$C$2 -> 6000 | E49: =(Traffic!E49*Kanäle!$C$32)*Kanäle!$C$2 -> 6000 | F49: =(Traffic!F49*Kanäle!$C$32)*Kanäle!$C$2 -> 6000 | G49: =(Traffic!G49*Kanäle!$C$32)*Kanäle!$C$2 -> 6000 | H49: =(Traffic!H49*Kanäle!$C$32)*Kanäle!$C$2 -> 6000 | I49: =(Traffic!I49*Kanäle!$C$32)*Kanäle!$C$2 -> 6000 | J49: =(Traffic!J49*Kanäle!$C$32)*Kanäle!$C$2 -> 6000 | ... N49: =(Traffic!N49*Kanäle!$C$32)*Kanäle!$C$2 -> 6000 | O49: =SUM(C49:N49) -> 72000
B50: Newsletter | C50: =(Traffic!C50*Kanäle!$C$36)*Kanäle!$C$2 -> 106066.27 | D50: =(Traffic!D50*Kanäle!$C$36)*Kanäle!$C$2 -> 116026.73 | E50: =(Traffic!E50*Kanäle!$C$36)*Kanäle!$C$2 -> 127987.2 | F50: =(Traffic!F50*Kanäle!$C$36)*Kanäle!$C$2 -> 139547.66 | G50: =(Traffic!G50*Kanäle!$C$36)*Kanäle!$C$2 -> 150708.13 | H50: =(Traffic!H50*Kanäle!$C$36)*Kanäle!$C$2 -> 163868.59 | I50: =(Traffic!I50*Kanäle!$C$36)*Kanäle!$C$2 -> 176629.06 | J50: =(Traffic!J50*Kanäle!$C$36)*Kanäle!$C$2 -> 188989.52 | ... N50: =(Traffic!N50*Kanäle!$C$36)*Kanäle!$C$2 -> 246431.38 | O50: =SUM(C50:N50) -> 2067785.9
B51: TypeIn | C51: =(Traffic!C51*Kanäle!$B$2)*Kanäle!$C$2 -> 39708.174 | D51: =(Traffic!D51*Kanäle!$B$2)*Kanäle!$C$2 -> 41698.494 | E51: =(Traffic!E51*Kanäle!$B$2)*Kanäle!$C$2 -> 45793.143 | F51: =(Traffic!F51*Kanäle!$B$2)*Kanäle!$C$2 -> 48227.553 | G51: =(Traffic!G51*Kanäle!$B$2)*Kanäle!$C$2 -> 50818.701 | H51: =(Traffic!H51*Kanäle!$B$2)*Kanäle!$C$2 -> 55565.26 | I51: =(Traffic!I51*Kanäle!$B$2)*Kanäle!$C$2 -> 58707.772 | J51: =(Traffic!J51*Kanäle!$B$2)*Kanäle!$C$2 -> 62068.831 | ... N51: =(Traffic!N51*Kanäle!$B$2)*Kanäle!$C$2 -> 82734.438 | O51: =SUM(C51:N51) -> 700748.67
B52: TOTALS | C52: =SUM(C43:C51) -> 499707.64 | D52: =SUM(D43:D51) -> 523091.28 | E52: =SUM(E43:E51) -> 576122.53 | F52: =SUM(F43:F51) -> 604791.16 | G52: =SUM(G43:G51) -> 635083.9 | H52: =SUM(H43:H51) -> 695586.17 | I52: =SUM(I43:I51) -> 732343.91 | J52: =SUM(J43:J51) -> 771405.68 | ... O52: =SUM(O43:O51) -> 8727995.8

Sheet Gewinn
B1: ONLINE MARKETING GEWINN
B4: 2022 | C4: Q1 | F4: Q2 | I4: Q3 | L4: Q4 | O4: WIN YEAR TOTALS
C5: JAN | D5: FEB | E5: MAR | F5: APR | G5: MAY | H5: JUN | I5: JUL | J5: AUG | K5: SEPT | L5: OCT | M5: NOV | N5: DEC
B6: Marketing Maßnahmen | C6: =SUM(C7:C15) -> 0 | D6: =SUM(D7:D15) -> 0 | E6: =SUM(E7:E15) -> 5386.2069 | F6: =SUM(F7:F15) -> 7263.0517 | G6: =SUM(G7:G15) -> 9132.3405 | H6: =SUM(H7:H15) -> 11468.952 | I6: =SUM(I7:I15) -> 14500.841 | J6: =SUM(J7:J15) -> 18179.578 | ... N6: =SUM(N7:N15) -> 39692.344 | O6: =SUM(C6:N6) -> 180783.2
B7: SEO | C7: =(Umsatz!C7*Kanäle!$D$2)-'Digital Marketing Budget'!C7-'Digital Marketing Budget'!C8 -> 0 | D7: =(Umsatz!D7*Kanäle!$D$2)-'Digital Marketing Budget'!D7-'Digital Marketing Budget'!D8 -> 0 | E7: =(Umsatz!E7*Kanäle!$D$2)-'Digital Marketing Budget'!E7-'Digital Marketing Budget'!E8 -> 2275.8621 | F7: =(Umsatz!F7*Kanäle!$D$2)-'Digital Marketing Budget'!F7-'Digital Marketing Budget'!F8 -> 2844.8276 | G7: =(Umsatz!G7*Kanäle!$D$2)-'Digital Marketing Budget'!G7-'Digital Marketing Budget'!G8 -> 3556.0345 | H7: =(Umsatz!H7*Kanäle!$D$2)-'Digital Marketing Budget'!H7-'Digital Marketing Budget'!H8 -> 4445.0431 | I7: =(Umsatz!I7*Kanäle!$D$2)-'Digital Marketing Budget'!I7-'Digital Marketing Budget'!I8 -> 5556.3039 | J7: =(Umsatz!J7*Kanäle!$D$2)-'Digital Marketing Budget'!J7-'Digital Marketing Budget'!J8 -> 6945.3798 | ... N7: =(Umsatz!N7*Kanäle!$D$2)-'Digital Marketing Budget'!N7-'Digital Marketing Budget'!N8 -> 11956.494 | O7: =SUM(C7:N7) -> 60679.021
C8: 0 | D8: 0 | E8: 0 | F8: 0 | G8: 0 | H8: 0 | I8: 0 | J8: 0 | K8: 0 | L8: 0 | M8: 0 | N8: 0 | O8: =SUM(C8:N8) -> 0
B9: Content Marketing | C9: =Umsatz!C9*Kanäle!$D$2-'Digital Marketing Budget'!C9 -> 0 | D9: =Umsatz!D9*Kanäle!$D$2-'Digital Marketing Budget'!D9 -> 0 | E9: =Umsatz!E9*Kanäle!$D$2-'Digital Marketing Budget'!E9 -> 3034.4828 | F9: =Umsatz!F9*Kanäle!$D$2-'Digital Marketing Budget'!F9 -> 3793.1034 | G9: =Umsatz!G9*Kanäle!$D$2-'Digital Marketing Budget'!G9 -> 4741.3793 | H9: =Umsatz!H9*Kanäle!$D$2-'Digital Marketing Budget'!H9 -> 5926.7241 | I9: =Umsatz!I9*Kanäle!$D$2-'Digital Marketing Budget'!I9 -> 7408.4052 | J9: =Umsatz!J9*Kanäle!$D$2-'Digital Marketing Budget'!J9 -> 9260.5065 | ... N9: =Umsatz!N9*Kanäle!$D$2-'Digital Marketing Budget'!N9 -> 22608.658 | O9: =SUM(C9:N9) -> 100905.36
B10: Pay-Per-Click Marketing | C10: =(Umsatz!C10*Kanäle!$D$2)-'Digital Marketing Budget'!C10 -> 0 | D10: =(Umsatz!D10*Kanäle!$D$2)-'Digital Marketing Budget'!D10 -> 0 | E10: =(Umsatz!E10*Kanäle!$D$2)-'Digital Marketing Budget'!E10 -> 0 | F10: =(Umsatz!F10*Kanäle!$D$2)-'Digital Marketing Budget'!F10 -> 0 | G10: =(Umsatz!G10*Kanäle!$D$2)-'Digital Marketing Budget'!G10 -> 0 | H10: =(Umsatz!H10*Kanäle!$D$2)-'Digital Marketing Budget'!H10 -> 0 | I10: =(Umsatz!I10*Kanäle!$D$2)-'Digital Marketing Budget'!I10 -> 0 | J10: =(Umsatz!J10*Kanäle!$D$2)-'Digital Marketing Budget'!J10 -> 0 | ... N10: =(Umsatz!N10*Kanäle!$D$2)-'Digital Marketing Budget'!N10 -> 0 | O10: =SUM(C10:N10) -> 0
B11: Display Advertising | C11: =Umsatz!C11*Kanäle!$D$2-'Digital Marketing Budget'!C11 -> 0 | D11: =Umsatz!D11*Kanäle!$D$2-'Digital Marketing Budget'!D11 -> 0 | E11: =Umsatz!E11*Kanäle!$D$2-'Digital Marketing Budget'!E11 -> 0 | F11: =Umsatz!F11*Kanäle!$D$2-'Digital Marketing Budget'!F11 -> 0 | G11: =Umsatz!G11*Kanäle!$D$2-'Digital Marketing Budget'!G11 -> 0 | H11: =Umsatz!H11*Kanäle!$D$2-'Digital Marketing Budget'!H11 -> 0 | I11: =Umsatz!I11*Kanäle!$D$2-'Digital Marketing Budget'!I11 -> 0 | J11: =Umsatz!J11*Kanäle!$D$2-'Digital Marketing Budget'!J11 -> 0 | ... N11: =Umsatz!N11*Kanäle!$D$2-'Digital Marketing Budget'!N11 -> 0 | O11: =SUM(C11:N11) -> 0
B12: Retargeting | C12: =Umsatz!C12*Kanäle!$D$2-'Digital Marketing Budget'!C12 -> 0 | D12: =Umsatz!D12*Kanäle!$D$2-'Digital Marketing Budget'!D12 -> 0 | E12: =Umsatz!E12*Kanäle!$D$2-'Digital Marketing Budget'!E12 -> 0 | F12: =Umsatz!F12*Kanäle!$D$2-'Digital Marketing Budget'!F12 -> 0 | G12: =Umsatz!G12*Kanäle!$D$2-'Digital Marketing Budget'!G12 -> 0 | H12: =Umsatz!H12*Kanäle!$D$2-'Digital Marketing Budget'!H12 -> 0 | I12: =Umsatz!I12*Kanäle!$D$2-'Digital Marketing Budget'!I12 -> 0 | J12: =Umsatz!J12*Kanäle!$D$2-'Digital Marketing Budget'!J12 -> 0 | ... N12: =Umsatz!N12*Kanäle!$D$2-'Digital Marketing Budget'!N12 -> 0 | O12: =SUM(C12:N12) -> 0
B13: Social Media | C13: =Umsatz!C13*Kanäle!$D$2-'Digital Marketing Budget'!C13 -> 0 | D13: =Umsatz!D13*Kanäle!$D$2-'Digital Marketing Budget'!D13 -> 0 | E13: =Umsatz!E13*Kanäle!$D$2-'Digital Marketing Budget'!E13 -> 75.862069 | F13: =Umsatz!F13*Kanäle!$D$2-'Digital Marketing Budget'!F13 -> 37.931034 | G13: =Umsatz!G13*Kanäle!$D$2-'Digital Marketing Budget'!G13 -> 47.413793 | H13: =Umsatz!H13*Kanäle!$D$2-'Digital Marketing Budget'!H13 -> 59.267241 | I13: =Umsatz!I13*Kanäle!$D$2-'Digital Marketing Budget'!I13 -> 185.21013 | J13: =Umsatz!J13*Kanäle!$D$2-'Digital Marketing Budget'!J13 -> 231.51266 | ... N13: =Umsatz!N13*Kanäle!$D$2-'Digital Marketing Budget'!N13 -> 565.21646 | O13: =SUM(C13:N13) -> 2305.7159
B14: Newsletter | C14: =Umsatz!C14*Kanäle!$D$2-'Digital Marketing Budget'!C14 -> 0 | D14: =Umsatz!D14*Kanäle!$D$2-'Digital Marketing Budget'!D14 -> 0 | E14: =Umsatz!E14*Kanäle!$D$2-'Digital Marketing Budget'!E14 -> 0 | F14: =Umsatz!F14*Kanäle!$D$2-'Digital Marketing Budget'!F14 -> -13.068966 | G14: =Umsatz!G14*Kanäle!$D$2-'Digital Marketing Budget'!G14 -> 34.344828 | H14: =Umsatz!H14*Kanäle!$D$2-'Digital Marketing Budget'!H14 -> 93.612069 | I14: =Umsatz!I14*Kanäle!$D$2-'Digital Marketing Budget'!I14 -> 167.69612 | J14: =Umsatz!J14*Kanäle!$D$2-'Digital Marketing Budget'!J14 -> 260.30119 | ... N14: =Umsatz!N14*Kanäle!$D$2-'Digital Marketing Budget'!N14 -> 927.70878 | O14: =SUM(C14:N14) -> 3069.0267
B15: TypeIn | C15: =Umsatz!C15*Kanäle!$D$2 -> 0 | D15: =Umsatz!D15*Kanäle!$D$2 -> 0 | E15: =Umsatz!E15*Kanäle!$D$2 -> 0 | F15: =Umsatz!F15*Kanäle!$D$2 -> 600.25862 | G15: =Umsatz!G15*Kanäle!$D$2 -> 753.1681 | H15: =Umsatz!H15*Kanäle!$D$2 -> 944.30496 | I15: =Umsatz!I15*Kanäle!$D$2 -> 1183.226 | J15: =Umsatz!J15*Kanäle!$D$2 -> 1481.8774 | K15: 0 | L15: =Umsatz!L15*Kanäle!$D$2 -> 2321.8342 | M15: =Umsatz!M15*Kanäle!$D$2 -> 2905.1376 | N15: =Umsatz!N15*Kanäle!$D$2 -> 3634.2669 | O15: =SUM(C15:N15) -> 13824.074
B16: TOTALS | C16: =SUM(C7:C15) -> 0 | D16: =SUM(D7:D15) -> 0 | E16: =SUM(E7:E15) -> 5386.2069 | F16: =SUM(F7:F15) -> 7263.0517 | G16: =SUM(G7:G15) -> 9132.3405 | H16: =SUM(H7:H15) -> 11468.952 | I16: =SUM(I7:I15) -> 14500.841 | J16: =SUM(J7:J15) -> 18179.578 | ... O16: =SUM(O7:O15) -> 180783.2
B22: 2023 | C22: Q1 | F22: Q2 | I22: Q3 | L22: Q4 | O22: WIN YEAR TOTALS
C23: JAN | D23: FEB | E23: MAR | F23: APR | G23: MAY | H23: JUN | I23: JUL | J23: AUG | K23: SEPT | L23: OCT | M23: NOV | N23: DEC
B24: Marketing Maßnahmen | C24: =SUM(C25:C33) -> 63673.905 | D24: =SUM(D25:D33) -> 68520.756 | E24: =SUM(E25:E33) -> 79804.268 | F24: =SUM(F25:F33) -> 84218.991 | G24: =SUM(G25:G33) -> 90811.35 | H24: =SUM(H25:H33) -> 105141.62 | I24: =SUM(I25:I33) -> 107484.56 | J24: =SUM(J25:J33) -> 116355.69 | ... N24: =SUM(N25:N33) -> 156860.54 | O24: =SUM(C24:N24) -> 1286933.7
B25: SEO | C25: =(Umsatz!C25*Kanäle!$D$2)-'Digital Marketing Budget'!C25-'Digital Marketing Budget'!C26 -> 13097.143 | D25: =(Umsatz!D25*Kanäle!$D$2)-'Digital Marketing Budget'!D25-'Digital Marketing Budget'!D26 -> 18007.357 | E25: =(Umsatz!E25*Kanäle!$D$2)-'Digital Marketing Budget'!E25-'Digital Marketing Budget'!E26 -> 20059.093 | F25: =(Umsatz!F25*Kanäle!$D$2)-'Digital Marketing Budget'!F25-'Digital Marketing Budget'!F26 -> 22316.003 | G25: =(Umsatz!G25*Kanäle!$D$2)-'Digital Marketing Budget'!G25-'Digital Marketing Budget'!G26 -> 27308.603 | H25: =(Umsatz!H25*Kanäle!$D$2)-'Digital Marketing Budget'!H25-'Digital Marketing Budget'!H26 -> 29590.213 | I25: =(Umsatz!I25*Kanäle!$D$2)-'Digital Marketing Budget'!I25-'Digital Marketing Budget'!I26 -> 32893.659 | J25: =(Umsatz!J25*Kanäle!$D$2)-'Digital Marketing Budget'!J25-'Digital Marketing Budget'!J26 -> 36198 | ... N25: =(Umsatz!N25*Kanäle!$D$2)-'Digital Marketing Budget'!N25-'Digital Marketing Budget'!N26 -> 53066.991 | O25: =SUM(C25:N25) -> 384429.97
C26: 0 | D26: 0 | E26: 0 | F26: 0 | G26: 0 | H26: 0 | I26: 0 | J26: 0 | K26: 0 | L26: 0 | M26: 0 | N26: 0 | O26: =SUM(C26:N26) -> 0
B27: Content Marketing | C27: =Umsatz!C27*Kanäle!$D$2-'Digital Marketing Budget'!C27 -> 21091.417 | D27: =Umsatz!D27*Kanäle!$D$2-'Digital Marketing Budget'!D27 -> 19574.176 | E27: =Umsatz!E27*Kanäle!$D$2-'Digital Marketing Budget'!E27 -> 26787.933 | F27: =Umsatz!F27*Kanäle!$D$2-'Digital Marketing Budget'!F27 -> 25518.991 | G27: =Umsatz!G27*Kanäle!$D$2-'Digital Marketing Budget'!G27 -> 24001.75 | H27: =Umsatz!H27*Kanäle!$D$2-'Digital Marketing Budget'!H27 -> 31587.957 | I27: =Umsatz!I27*Kanäle!$D$2-'Digital Marketing Budget'!I27 -> 26966.865 | J27: =Umsatz!J27*Kanäle!$D$2-'Digital Marketing Budget'!J27 -> 28677.624 | ... N27: =Umsatz!N27*Kanäle!$D$2-'Digital Marketing Budget'!N27 -> 40815.555 | O27: =SUM(C27:N27) -> 348694.03
B28: Pay-Per-Click Marketing | C28: =(Umsatz!C28*Kanäle!$D$2)-'Digital Marketing Budget'!C28 -> 4543.4724 | D28: =(Umsatz!D28*Kanäle!$D$2)-'Digital Marketing Budget'!D28 -> 3739.5724 | E28: =(Umsatz!E28*Kanäle!$D$2)-'Digital Marketing Budget'!E28 -> 2383.9424 | F28: =(Umsatz!F28*Kanäle!$D$2)-'Digital Marketing Budget'!F28 -> 2571.6024 | G28: =(Umsatz!G28*Kanäle!$D$2)-'Digital Marketing Budget'!G28 -> 2853.0224 | H28: =(Umsatz!H28*Kanäle!$D$2)-'Digital Marketing Budget'!H28 -> 2946.0324 | I28: =(Umsatz!I28*Kanäle!$D$2)-'Digital Marketing Budget'!I28 -> 3043.9024 | J28: =(Umsatz!J28*Kanäle!$D$2)-'Digital Marketing Budget'!J28 -> 3457.2524 | ... N28: =(Umsatz!N28*Kanäle!$D$2)-'Digital Marketing Budget'!N28 -> -1763.2976 | O28: =SUM(C28:N28) -> 31554.919
B29: Display Advertising | C29: =Umsatz!C29*Kanäle!$D$2-'Digital Marketing Budget'!C29 -> 9155.1724 | D29: =Umsatz!D29*Kanäle!$D$2-'Digital Marketing Budget'!D29 -> 9155.1724 | E29: =Umsatz!E29*Kanäle!$D$2-'Digital Marketing Budget'!E29 -> 9155.1724 | F29: =Umsatz!F29*Kanäle!$D$2-'Digital Marketing Budget'!F29 -> 9155.1724 | G29: =Umsatz!G29*Kanäle!$D$2-'Digital Marketing Budget'!G29 -> 9155.1724 | H29: =Umsatz!H29*Kanäle!$D$2-'Digital Marketing Budget'!H29 -> 9155.1724 | I29: =Umsatz!I29*Kanäle!$D$2-'Digital Marketing Budget'!I29 -> 9155.1724 | J29: =Umsatz!J29*Kanäle!$D$2-'Digital Marketing Budget'!J29 -> 9155.1724 | ... N29: =Umsatz!N29*Kanäle!$D$2-'Digital Marketing Budget'!N29 -> 9155.1724 | O29: =SUM(C29:N29) -> 109862.07
B30: Retargeting | C30: =Umsatz!C30*Kanäle!$D$2-'Digital Marketing Budget'!C30 -> 5702.5862 | D30: =Umsatz!D30*Kanäle!$D$2-'Digital Marketing Budget'!D30 -> 5702.5862 | E30: =Umsatz!E30*Kanäle!$D$2-'Digital Marketing Budget'!E30 -> 5702.5862 | F30: =Umsatz!F30*Kanäle!$D$2-'Digital Marketing Budget'!F30 -> 5702.5862 | G30: =Umsatz!G30*Kanäle!$D$2-'Digital Marketing Budget'!G30 -> 5702.5862 | H30: =Umsatz!H30*Kanäle!$D$2-'Digital Marketing Budget'!H30 -> 5702.5862 | I30: =Umsatz!I30*Kanäle!$D$2-'Digital Marketing Budget'!I30 -> 5702.5862 | J30: =Umsatz!J30*Kanäle!$D$2-'Digital Marketing Budget'!J30 -> 5702.5862 | ... N30: =Umsatz!N30*Kanäle!$D$2-'Digital Marketing Budget'!N30 -> 5702.5862 | O30: =SUM(C30:N30) -> 68431.034
B31: Social Media | C31: =Umsatz!C31*Kanäle!$D$2-'Digital Marketing Budget'!C31 -> 621.7381 | D31: =Umsatz!D31*Kanäle!$D$2-'Digital Marketing Budget'!D31 -> 683.91192 | E31: =Umsatz!E31*Kanäle!$D$2-'Digital Marketing Budget'!E31 -> 343.16311 | F31: =Umsatz!F31*Kanäle!$D$2-'Digital Marketing Budget'!F31 -> 691.15342 | G31: =Umsatz!G31*Kanäle!$D$2-'Digital Marketing Budget'!G31 -> 773.90676 | H31: =Umsatz!H31*Kanäle!$D$2-'Digital Marketing Budget'!H31 -> 864.93544 | I31: =Umsatz!I31*Kanäle!$D$2-'Digital Marketing Budget'!I31 -> 965.06698 | J31: =Umsatz!J31*Kanäle!$D$2-'Digital Marketing Budget'!J31 -> 1075.2117 | ... N31: =Umsatz!N31*Kanäle!$D$2-'Digital Marketing Budget'!N31 -> -565.68863 | O31: =SUM(C31:N31) -> 8662.3741
B32: Newsletter | C32: =Umsatz!C32*Kanäle!$D$2-'Digital Marketing Budget'!C32 -> 3036.8505 | D32: =Umsatz!D32*Kanäle!$D$2-'Digital Marketing Budget'!D32 -> 4994.268 | E32: =Umsatz!E32*Kanäle!$D$2-'Digital Marketing Budget'!E32 -> 7710.3063 | F32: =Umsatz!F32*Kanäle!$D$2-'Digital Marketing Budget'!F32 -> 10274.62 | G32: =Umsatz!G32*Kanäle!$D$2-'Digital Marketing Budget'!G32 -> 12687.21 | H32: =Umsatz!H32*Kanäle!$D$2-'Digital Marketing Budget'!H32 -> 15858.421 | I32: =Umsatz!I32*Kanäle!$D$2-'Digital Marketing Budget'!I32 -> 18877.908 | J32: =Umsatz!J32*Kanäle!$D$2-'Digital Marketing Budget'!J32 -> 21745.67 | ... N32: =Umsatz!N32*Kanäle!$D$2-'Digital Marketing Budget'!N32 -> 36251.202 | O32: =SUM(C32:N32) -> 217824.87
B33: TypeIn | C33: =Umsatz!C33*Kanäle!$D$2 -> 6425.5256 | D33: =Umsatz!D33*Kanäle!$D$2 -> 6663.7124 | E33: =Umsatz!E33*Kanäle!$D$2 -> 7662.0717 | F33: =Umsatz!F33*Kanäle!$D$2 -> 7988.8622 | G33: =Umsatz!G33*Kanäle!$D$2 -> 8329.0994 | H33: =Umsatz!H33*Kanäle!$D$2 -> 9436.3003 | I33: =Umsatz!I33*Kanäle!$D$2 -> 9879.4028 | J33: =Umsatz!J33*Kanäle!$D$2 -> 10344.169 | ... N33: =Umsatz!N33*Kanäle!$D$2 -> 14198.018 | O33: =SUM(C33:N33) -> 117474.42
B34: TOTALS | C34: =SUM(C25:C33) -> 63673.905 | D34: =SUM(D25:D33) -> 68520.756 | E34: =SUM(E25:E33) -> 79804.268 | F34: =SUM(F25:F33) -> 84218.991 | G34: =SUM(G25:G33) -> 90811.35 | H34: =SUM(H25:H33) -> 105141.62 | I34: =SUM(I25:I33) -> 107484.56 | J34: =SUM(J25:J33) -> 116355.69 | ... O34: =SUM(O25:O33) -> 1286933.7
B40: 2024 | C40: Q1 | F40: Q2 | I40: Q3 | L40: Q4 | O40: WIN YEAR TOTALS
C41: JAN | D41: FEB | E41: MAR | F41: APR | G41: MAY | H41: JUN | I41: JUL | J41: AUG | K41: SEPT | L41: OCT | M41: NOV | N41: DEC
B42: Marketing Maßnahmen | C42: =SUM(C43:C51) -> 172140.48 | D42: =SUM(D43:D51) -> 180333.75 | E42: =SUM(E43:E51) -> 200177.82 | F42: =SUM(F43:F51) -> 206621.62 | G42: =SUM(G43:G51) -> 219300.61 | H42: =SUM(H43:H51) -> 218198.12 | I42: =SUM(I43:I51) -> 255642.13 | J42: =SUM(J43:J51) -> 270458.42 | ... N42: =SUM(N43:N51) -> 363526.36 | O42: =SUM(C42:N42) -> 3022146.9
B43: SEO | C43: =(Umsatz!C43*Kanäle!$D$2)-'Digital Marketing Budget'!C43-'Digital Marketing Budget'!C44 -> 58388.665 | D43: =(Umsatz!D43*Kanäle!$D$2)-'Digital Marketing Budget'!D43-'Digital Marketing Budget'!D44 -> 64242.507 | E43: =(Umsatz!E43*Kanäle!$D$2)-'Digital Marketing Budget'!E43-'Digital Marketing Budget'!E44 -> 70681.733 | F43: =(Umsatz!F43*Kanäle!$D$2)-'Digital Marketing Budget'!F43-'Digital Marketing Budget'!F44 -> 77914.631 | G43: =(Umsatz!G43*Kanäle!$D$2)-'Digital Marketing Budget'!G43-'Digital Marketing Budget'!G44 -> 85706.094 | H43: =(Umsatz!H43*Kanäle!$D$2)-'Digital Marketing Budget'!H43-'Digital Marketing Budget'!H44 -> 94276.703 | I43: =(Umsatz!I43*Kanäle!$D$2)-'Digital Marketing Budget'!I43-'Digital Marketing Budget'!I44 -> 103704.37 | J43: =(Umsatz!J43*Kanäle!$D$2)-'Digital Marketing Budget'!J43-'Digital Marketing Budget'!J44 -> 113775.31 | ... N43: =(Umsatz!N43*Kanäle!$D$2)-'Digital Marketing Budget'!N43-'Digital Marketing Budget'!N44 -> 166741.39 | O43: =SUM(C43:N43) -> 1250442.4
C44: 0 | D44: 0 | E44: 0 | F44: 0 | G44: 0 | H44: 0 | I44: 0 | J44: 0 | K44: 0 | L44: 0 | M44: 0 | N44: 0 | O44: =SUM(C44:N44) -> 0
B45: Content Marketing | C45: =Umsatz!C45*Kanäle!$D$2-'Digital Marketing Budget'!C45 -> 39298.314 | D45: =Umsatz!D45*Kanäle!$D$2-'Digital Marketing Budget'!D45 -> 37781.072 | E45: =Umsatz!E45*Kanäle!$D$2-'Digital Marketing Budget'!E45 -> 45367.279 | F45: =Umsatz!F45*Kanäle!$D$2-'Digital Marketing Budget'!F45 -> 43850.038 | G45: =Umsatz!G45*Kanäle!$D$2-'Digital Marketing Budget'!G45 -> 42332.796 | H45: =Umsatz!H45*Kanäle!$D$2-'Digital Marketing Budget'!H45 -> 49919.003 | I45: =Umsatz!I45*Kanäle!$D$2-'Digital Marketing Budget'!I45 -> 46787.762 | J45: =Umsatz!J45*Kanäle!$D$2-'Digital Marketing Budget'!J45 -> 45270.52 | ... N45: =Umsatz!N45*Kanäle!$D$2-'Digital Marketing Budget'!N45 -> 58783.161 | O45: =SUM(C45:N45) -> 567771.82
B46: Pay-Per-Click Marketing | C46: =(Umsatz!C46*Kanäle!$D$2)-'Digital Marketing Budget'!C46 -> 2209.4524 | D46: =(Umsatz!D46*Kanäle!$D$2)-'Digital Marketing Budget'!D46 -> 1532.9424 | E46: =(Umsatz!E46*Kanäle!$D$2)-'Digital Marketing Budget'!E46 -> 1261.7024 | F46: =(Umsatz!F46*Kanäle!$D$2)-'Digital Marketing Budget'!F46 -> -3318.5476 | G46: =(Umsatz!G46*Kanäle!$D$2)-'Digital Marketing Budget'!G46 -> -2129.9076 | H46: =(Umsatz!H46*Kanäle!$D$2)-'Digital Marketing Budget'!H46 -> -26181.538 | I46: =(Umsatz!I46*Kanäle!$D$2)-'Digital Marketing Budget'!I46 -> -1066.1176 | J46: =(Umsatz!J46*Kanäle!$D$2)-'Digital Marketing Budget'!J46 -> -766.85759 | ... N46: =(Umsatz!N46*Kanäle!$D$2)-'Digital Marketing Budget'!N46 -> -3454.3476 | O46: =SUM(C46:N46) -> -47843.081
B47: Display Advertising | C47: =Umsatz!C47*Kanäle!$D$2-'Digital Marketing Budget'!C47 -> 9155.1724 | D47: =Umsatz!D47*Kanäle!$D$2-'Digital Marketing Budget'!D47 -> 9155.1724 | E47: =Umsatz!E47*Kanäle!$D$2-'Digital Marketing Budget'!E47 -> 9155.1724 | F47: =Umsatz!F47*Kanäle!$D$2-'Digital Marketing Budget'!F47 -> 9155.1724 | G47: =Umsatz!G47*Kanäle!$D$2-'Digital Marketing Budget'!G47 -> 9155.1724 | H47: =Umsatz!H47*Kanäle!$D$2-'Digital Marketing Budget'!H47 -> 9155.1724 | I47: =Umsatz!I47*Kanäle!$D$2-'Digital Marketing Budget'!I47 -> 9155.1724 | J47: =Umsatz!J47*Kanäle!$D$2-'Digital Marketing Budget'!J47 -> 9155.1724 | ... N47: =Umsatz!N47*Kanäle!$D$2-'Digital Marketing Budget'!N47 -> 9155.1724 | O47: =SUM(C47:N47) -> 109862.07
B48: Retargeting | C48: =Umsatz!C48*Kanäle!$D$2-'Digital Marketing Budget'!C48 -> 5702.5862 | D48: =Umsatz!D48*Kanäle!$D$2-'Digital Marketing Budget'!D48 -> 5702.5862 | E48: =Umsatz!E48*Kanäle!$D$2-'Digital Marketing Budget'!E48 -> 5702.5862 | F48: =Umsatz!F48*Kanäle!$D$2-'Digital Marketing Budget'!F48 -> 5702.5862 | G48: =Umsatz!G48*Kanäle!$D$2-'Digital Marketing Budget'!G48 -> 5702.5862 | H48: =Umsatz!H48*Kanäle!$D$2-'Digital Marketing Budget'!H48 -> 5702.5862 | I48: =Umsatz!I48*Kanäle!$D$2-'Digital Marketing Budget'!I48 -> 5702.5862 | J48: =Umsatz!J48*Kanäle!$D$2-'Digital Marketing Budget'!J48 -> 5702.5862 | ... N48: =Umsatz!N48*Kanäle!$D$2-'Digital Marketing Budget'!N48 -> 5702.5862 | O48: =SUM(C48:N48) -> 68431.034
B49: Social Media | C49: =Umsatz!C49*Kanäle!$D$2-'Digital Marketing Budget'!C49 -> 2143.5321 | D49: =Umsatz!D49*Kanäle!$D$2-'Digital Marketing Budget'!D49 -> 2143.6621 | E49: =Umsatz!E49*Kanäle!$D$2-'Digital Marketing Budget'!E49 -> 2143.6621 | F49: =Umsatz!F49*Kanäle!$D$2-'Digital Marketing Budget'!F49 -> 2143.6621 | G49: =Umsatz!G49*Kanäle!$D$2-'Digital Marketing Budget'!G49 -> 2143.6621 | H49: =Umsatz!H49*Kanäle!$D$2-'Digital Marketing Budget'!H49 -> 2143.6621 | I49: =Umsatz!I49*Kanäle!$D$2-'Digital Marketing Budget'!I49 -> 2143.6621 | J49: =Umsatz!J49*Kanäle!$D$2-'Digital Marketing Budget'!J49 -> 2143.6621 | ... N49: =Umsatz!N49*Kanäle!$D$2-'Digital Marketing Budget'!N49 -> 1793.3921 | O49: =SUM(C49:N49) -> 23960.925
B50: Newsletter | C50: =Umsatz!C50*Kanäle!$D$2-'Digital Marketing Budget'!C50 -> 40181.034 | D50: =Umsatz!D50*Kanäle!$D$2-'Digital Marketing Budget'!D50 -> 43959.141 | E50: =Umsatz!E50*Kanäle!$D$2-'Digital Marketing Budget'!E50 -> 48495.869 | F50: =Umsatz!F50*Kanäle!$D$2-'Digital Marketing Budget'!F50 -> 52880.873 | G50: =Umsatz!G50*Kanäle!$D$2-'Digital Marketing Budget'!G50 -> 57114.152 | H50: =Umsatz!H50*Kanäle!$D$2-'Digital Marketing Budget'!H50 -> 62106.052 | I50: =Umsatz!I50*Kanäle!$D$2-'Digital Marketing Budget'!I50 -> 66946.229 | J50: =Umsatz!J50*Kanäle!$D$2-'Digital Marketing Budget'!J50 -> 71634.681 | ... N50: =Umsatz!N50*Kanäle!$D$2-'Digital Marketing Budget'!N50 -> 93422.972 | O50: =SUM(C50:N50) -> 783720.58
B51: TypeIn | C51: =Umsatz!C51*Kanäle!$D$2 -> 15061.721 | D51: =Umsatz!D51*Kanäle!$D$2 -> 15816.67 | E51: =Umsatz!E51*Kanäle!$D$2 -> 17369.813 | F51: =Umsatz!F51*Kanäle!$D$2 -> 18293.21 | G51: =Umsatz!G51*Kanäle!$D$2 -> 19276.059 | H51: =Umsatz!H51*Kanäle!$D$2 -> 21076.478 | I51: =Umsatz!I51*Kanäle!$D$2 -> 22268.465 | J51: =Umsatz!J51*Kanäle!$D$2 -> 23543.35 | ... N51: =Umsatz!N51*Kanäle!$D$2 -> 31382.028 | O51: =SUM(C51:N51) -> 265801.22
B52: TOTALS | C52: =SUM(C43:C51) -> 172140.48 | D52: =SUM(D43:D51) -> 180333.75 | E52: =SUM(E43:E51) -> 200177.82 | F52: =SUM(F43:F51) -> 206621.62 | G52: =SUM(G43:G51) -> 219300.61 | H52: =SUM(H43:H51) -> 218198.12 | I52: =SUM(I43:I51) -> 255642.13 | J52: =SUM(J43:J51) -> 270458.42 | ... O52: =SUM(O43:O51) -> 3022146.9

Sheet Kanäle
B1: CV | C1: Warenkorb | D1: Marge
B2: 0.03 | C2: 200 | D2: =(290-35-145)/290 -> 0.37931034 | E2: =(290-35-145)/290 -> 0.37931034
C3: 200 | D3: 14.33 | E3: 55 | F3: =((55/100*35)) -> 19.25 | G3: =E3-F3-D3 -> 21.42
H4: Material | I4: VK | J4: Marketing
A5: Kanal | B5: CV | C5: 0.03 | H5: 14.33 | I5: 55 | J5: =((55/100*35)) -> 19.25 | K5: =I5-J5-H5 -> 21.42
A6: SEO Offpage | B6: Link Qualität 1 | C6: Link Qualität 2 | D6: Link Qualität 3 | E6: Link Qualität 4 | U6: Win | V6: FH | W6: weitere Kosten
A7: interne Kosten | S7: Warenkorbwert | T7: 29 | U7: 27 | V7: 3 | W7: 15 | Y7: =T7/29*100 -> 100 | Z7: =U7/29*100 -> 93.103448 | AA7: =V7/29*100 -> 10.344828 | AB7: =W7/29*100 -> 51.724138 | AC7: =Z7-AB7-AA7 -> 31.034483
A8: Traffic
A10: SEO Onpage | B10: Content | C10: Produkte | D10: Gesamt | E10: Seitenarchitektur
A11: interne Kosten
A12: Traffic
B13: CV | C13: 0.04
A14: Content Marketing | B14: Website | C14: Content | D14: Grafik | E14: Kooperationen | F14: Seeding | G14: Design
A15: interne Kosten
A16: Traffic
B17: CV | C17: 0.04
A18: PPC | B18: Bid Management | C18: interne Kosten | D18: Texte Top 100 | E18: Google Adwords | F18: Social Ads
A19: Kosten | B19: 0 | D19: 0 | E19: =(1*75*30)*1 -> 2250 | F19: =(1*75*30)*1 -> 2250
A20: Traffic | B20: 0 | C20: 0 | D20: 0 | E20: =1*75*30 -> 2250 | F20: =1*75*30 -> 2250
A21: View | B21: 0 | C21: 0 | D21: 0 | E21: =E20/0.1 -> 22500 | F21: =F20/0.1 -> 22500
B22: CV | C22: 0.04
A23: CPM | B23: Texte Top 100 | C23: Google Adwords | D23: Facebook Ads
A24: Kosten | B24: 0 | C24: =(1*75*30)*1 -> 2250 | D24: =(1*75*30)*1 -> 2250
A25: Traffic | B25: 0 | C25: =1*75*30 -> 2250 | D25: =1*75*30 -> 2250
A26: View | B26: 0 | C26: =C25/0.1 -> 22500 | D26: =D25/0.1 -> 22500
B27: CV | C27: 0.04
A28: Retargeting | B28: Retargeting | C28: Texte Top 100
A29: Kosten | B29: =(((1*75*30)+(1*75*30))*0.5)/2 -> 1125 | C29: 500
A30: Traffic | B30: =((1*75*30)+(1*75*30))/2 -> 2250
A31: View | B31: =B30/0.05 -> 45000
B32: CV | C32: 0.01
A33: Social Media | B33: Aktionen | C33: Redaktion | D33: Software
A34: interne Kosten | B34: 2000 | C34: 500 | D34: 500
A35: Likes | B35: 2000
C36: 0.04
A37: Newsletter | B37: Software | C37: Neue Adressen
A38: interne Kosten | B38: 50 | C38: 1
A39: Traffic
A41: Conversion Optimization | B41: Multivariate Tests
